Workbook

Sheet Sheet1
A1: Paper | B1: P | C1: T | D1: rho_v | E1: rho_l
A2: 357 | B2: ='0357'!D2 -> 1166757.4 | C2: ='0357'!E2 -> 303.15 | D2: ='0357'!F2 -> nan | E2: ='0357'!G2 -> nan
A3: 357 | B3: ='0357'!D3 -> 1554629.5 | C3: ='0357'!E3 -> 313.15 | D3: ='0357'!F3 -> nan | E3: ='0357'!G3 -> nan
A4: 357 | B4: ='0357'!D4 -> 2033998.1 | C4: ='0357'!E4 -> 323.15 | D4: ='0357'!F4 -> nan | E4: ='0357'!G4 -> nan
A5: 357 | B5: ='0357'!D5 -> 2615704.9 | C5: ='0357'!E5 -> 333.15 | D5: ='0357'!F5 -> nan | E5: ='0357'!G5 -> nan
A6: 357 | B6: ='0357'!D6 -> 3315050 | C6: ='0357'!E6 -> 343.15 | D6: ='0357'!F6 -> nan | E6: ='0357'!G6 -> nan
A7: 357 | B7: ='0357'!D7 -> 4143584.5 | C7: ='0357'!E7 -> 353.15 | D7: ='0357'!F7 -> nan | E7: ='0357'!G7 -> nan
A8: 357 | B8: ='0357'!D8 -> 5119547 | C8: ='0357'!E8 -> 363.15 | D8: ='0357'!F8 -> nan | E8: ='0357'!G8 -> nan
A9: 357 | B9: ='0357'!D9 -> 6259757.2 | C9: ='0357'!E9 -> 373.15 | D9: ='0357'!F9 -> nan | E9: ='0357'!G9 -> nan
A10: 357 | B10: ='0357'!D10 -> 7582149.8 | C10: ='0357'!E10 -> 383.15 | D10: ='0357'!F10 -> nan | E10: ='0357'!G10 -> nan
A11: 357 | B11: ='0357'!D11 -> 9117223.5 | C11: ='0357'!E11 -> 393.15 | D11: ='0357'!F11 -> nan | E11: ='0357'!G11 -> nan
A12: 357 | B12: ='0357'!D12 -> 9975446.2 | C12: ='0357'!E12 -> 398.15 | D12: ='0357'!F12 -> nan | E12: ='0357'!G12 -> nan
A13: 357 | B13: ='0357'!D13 -> 10902570 | C13: ='0357'!E13 -> 403.15 | D13: ='0357'!F13 -> nan | E13: ='0357'!G13 -> nan
... A15: 357 | B15: ='0357'!D15 -> 11297738 | C15: ='0357'!E15 -> 405.15 | D15: ='0357'!F15 -> nan | E15: ='0357'!G15 -> nan
A16: 358 | B16: ='0358'!E2 -> 1011223.5 | C16: ='0358'!F2 -> 298.15 | D16: ='0358'!G2 -> 600.96298 | E16: ='0358'!H2 -> nan
A17: 358 | B17: ='0358'!E3 -> 2031566.2 | C17: ='0358'!F3 -> 323.15 | D17: ='0358'!G3 -> 561.83065 | E17: ='0358'!H3 -> nan
A18: 358 | B18: ='0358'!E4 -> 3706468.5 | C18: ='0358'!F4 -> 348.15 | D18: ='0358'!G4 -> 516.376 | E18: ='0358'!H4 -> nan
A19: 358 | B19: ='0358'!E5 -> 6246686.2 | C19: ='0358'!F5 -> 373.15 | D19: ='0358'!G5 -> 456.7044 | E19: ='0358'!H5 -> nan
A20: 358 | B20: ='0358'!E6 -> 9945048.8 | C20: ='0358'!F6 -> 398.15 | D20: ='0358'!G6 -> 357.53106 | E20: ='0358'!H6 -> nan
A21: 359 | B21: ='0359'!F2 -> 6246686.2 | C21: ='0359'!G2 -> 373.15 | D21: ='0359'!H2 -> 56.20065 | E21: ='0359'!I2 -> 456.58771
A22: 359 | B22: ='0359'!F3 -> 9945048.8 | C22: ='0359'!G3 -> 398.15 | D22: ='0359'!H3 -> 125.00387 | E22: ='0359'!I3 -> 357.6405
A23: 359 | B23: ='0359'!F4 -> 11060637 | C23: ='0359'!G4 -> 404.2 | D23: ='0359'!H4 -> 184.61062 | E23: ='0359'!I4 -> 292.07307
A24: 359 | B24: ='0359'!F5 -> 11154869 | C24: ='0359'!G5 -> 404.69 | D24: ='0359'!H5 -> 192.78526 | E24: ='0359'!I5 -> 280.49233
A25: 359 | B25: ='0359'!F6 -> 11253154 | C25: ='0359'!G6 -> 405.19 | D25: ='0359'!H6 -> 205.72844 | E25: ='0359'!I6 -> 267.54916
A26: 359 | B26: ='0359'!F7 -> 11302804 | C26: ='0359'!G7 -> 405.4 | D26: ='0359'!H7 -> 218.16071 | E26: ='0359'!I7 -> 252.73262
A27: 376 | B27: ='0376'!F2 -> 8666 | C27: ='0376'!G2 -> 200 | D27: ='0376'!H2 -> 0.089766607 | E27: ='0376'!I2 -> 728.86297
A28: 376 | B28: ='0376'!F3 -> 17790 | C28: ='0376'!G3 -> 210 | D28: ='0376'!H3 -> 0.17584582 | E28: ='0376'!I3 -> 717.36011
A29: 376 | B29: ='0376'!F4 -> 33910 | C29: ='0376'!G4 -> 220 | D29: ='0376'!H4 -> 0.29019995 | E29: ='0376'!I4 -> 705.7163
A30: 376 | B30: ='0376'!F5 -> 60610 | C30: ='0376'!G5 -> 230 | D30: ='0376'!H5 -> 0.55129831 | E30: ='0376'!I5 -> 693.96253
A31: 376 | B31: ='0376'!F6 -> 102580 | C31: ='0376'!G6 -> 240 | D31: ='0376'!H6 -> 0.9009009 | E31: ='0376'!I6 -> 681.66326
A32: 376 | B32: ='0376'!F7 -> 165360 | C32: ='0376'!G7 -> 250 | D32: ='0376'!H7 -> 1.4090064 | E32: ='0376'!I7 -> 668.89632
A33: 376 | B33: ='0376'!F8 -> 255900 | C33: ='0376'!G8 -> 260 | D33: ='0376'!H8 -> 2.1212957 | E33: ='0376'!I8 -> 656.16798
A34: 376 | B34: ='0376'!F9 -> 381900 | C34: ='0376'!G9 -> 270 | D34: ='0376'!H9 -> 3.0940594 | E34: ='0376'!I9 -> 642.67352
A35: 376 | B35: ='0376'!F10 -> 551800 | C35: ='0376'!G10 -> 280 | D35: ='0376'!H10 -> 4.3878894 | E35: ='0376'!I10 -> 629.32662
A36: 376 | B36: ='0376'!F11 -> 775300 | C36: ='0376'!G11 -> 290 | D36: ='0376'!H11 -> 6.0753341 | E36: ='0376'!I11 -> 615.00615
A37: 376 | B37: ='0376'!F12 -> 1062400 | C37: ='0376'!G12 -> 300 | D37: ='0376'!H12 -> 8.2440231 | E37: ='0376'!I12 -> 599.88002
A38: 376 | B38: ='0376'!F13 -> 1424900 | C38: ='0376'!G13 -> 310 | D38: ='0376'!H13 -> 11.024143 | E38: ='0376'!I13 -> 584.45354
... A48: 376 | B48: ='0376'!F23 -> 11300000 | C48: ='0376'!G23 -> 405.6 | D48: ='0376'!H23 -> 235.01763 | E48: ='0376'!I23 -> 235.01763
A49: 385 | B49: ='0385'!D2 -> 2325460 | C49: ='0385'!E2 -> 328.425 | D49: ='0385'!F2 -> nan | E49: ='0385'!G2 -> nan
A50: 385 | B50: ='0385'!D3 -> 2627690 | C50: ='0385'!E3 -> 333.368 | D50: ='0385'!F3 -> nan | E50: ='0385'!G3 -> nan
...

Sheet 0357
A1: P(atm) | B1: T© | D1: P | E1: T | F1: rho_v | G1: rho_l
A2: 11.515 | B2: 30 | D2: =A2*101325 -> 1166757.4 | E2: =B2+273.15 -> 303.15 | F2: nan | G2: nan
A3: 15.343 | B3: 40 | D3: =A3*101325 -> 1554629.5 | E3: =B3+273.15 -> 313.15 | F3: nan | G3: nan
A4: 20.074 | B4: 50 | D4: =A4*101325 -> 2033998.1 | E4: =B4+273.15 -> 323.15 | F4: nan | G4: nan
A5: 25.815 | B5: 60 | D5: =A5*101325 -> 2615704.9 | E5: =B5+273.15 -> 333.15 | F5: nan | G5: nan
A6: 32.717 | B6: 70 | D6: =A6*101325 -> 3315050 | E6: =B6+273.15 -> 343.15 | F6: nan | G6: nan
A7: 40.894 | B7: 80 | D7: =A7*101325 -> 4143584.5 | E7: =B7+273.15 -> 353.15 | F7: nan | G7: nan
A8: 50.526 | B8: 90 | D8: =A8*101325 -> 5119547 | E8: =B8+273.15 -> 363.15 | F8: nan | G8: nan
A9: 61.779 | B9: 100 | D9: =A9*101325 -> 6259757.2 | E9: =B9+273.15 -> 373.15 | F9: nan | G9: nan
A10: 74.83 | B10: 110 | D10: =A10*101325 -> 7582149.8 | E10: =B10+273.15 -> 383.15 | F10: nan | G10: nan
A11: 89.98 | B11: 120 | D11: =A11*101325 -> 9117223.5 | E11: =B11+273.15 -> 393.15 | F11: nan | G11: nan
A12: 98.45 | B12: 125 | D12: =A12*101325 -> 9975446.2 | E12: =B12+273.15 -> 398.15 | F12: nan | G12: nan
A13: 107.6 | B13: 130 | D13: =A13*101325 -> 10902570 | E13: =B13+273.15 -> 403.15 | F13: nan | G13: nan
... A15: 111.5 | B15: 132 | D15: =A15*101325 -> 11297738 | E15: =B15+273.15 -> 405.15 | F15: nan | G15: nan

Sheet 0358
A1: P(atm) | B1: T© | C1: Z | E1: P | F1: T | G1: rho_v | H1: rho_l | J1: R_NH3
A2: 9.98 | B2: 25 | C2: 0.01156 | E2: =A2*101325 -> 1011223.5 | F2: =B2+273.15 -> 298.15 | G2: =E2/(C2*$J$2*F2) -> 600.96298 | H2: nan | J2: 488.21013
A3: 20.05 | B3: 50 | C3: 0.02292 | E3: =A3*101325 -> 2031566.2 | F3: =B3+273.15 -> 323.15 | G3: =E3/(C3*$J$2*F3) -> 561.83065 | H3: nan
A4: 36.58 | B4: 75 | C4: 0.04223 | E4: =A4*101325 -> 3706468.5 | F4: =B4+273.15 -> 348.15 | G4: =E4/(C4*$J$2*F4) -> 516.376 | H4: nan
A5: 61.65 | B5: 100 | C5: 0.07508 | E5: =A5*101325 -> 6246686.2 | F5: =B5+273.15 -> 373.15 | G5: =E5/(C5*$J$2*F5) -> 456.7044 | H5: nan
A6: 98.15 | B6: 125 | C6: 0.1431 | E6: =A6*101325 -> 9945048.8 | F6: =B6+273.15 -> 398.15 | G6: =E6/(C6*$J$2*F6) -> 357.53106 | H6: nan

Sheet 0359
A1: P(atm) | B1: T© | C1: 1/Vg(mol/L) | D1: 1/Vl(mol/L) | F1: P | G1: T | H1: rho_v | I1: rho_l | K1: M_NH3
A2: 61.65 | B2: 100 | C2: 3.3 | D2: 26.81 | F2: =A2*101325 -> 6246686.2 | G2: =B2+273.15 -> 373.15 | H2: =C2*$K$2*1000 -> 56.20065 | I2: =D2*$K$2*1000 -> 456.58771 | K2: 0.0170305
A3: 98.15 | B3: 125 | C3: 7.34 | D3: 21 | F3: =A3*101325 -> 9945048.8 | G3: =B3+273.15 -> 398.15 | H3: =C3*$K$2*1000 -> 125.00387 | I3: =D3*$K$2*1000 -> 357.6405
A4: 109.16 | B4: 131.05 | C4: 10.84 | D4: 17.15 | F4: =A4*101325 -> 11060637 | G4: =B4+273.15 -> 404.2 | H4: =C4*$K$2*1000 -> 184.61062 | I4: =D4*$K$2*1000 -> 292.07307
A5: 110.09 | B5: 131.54 | C5: 11.32 | D5: 16.47 | F5: =A5*101325 -> 11154869 | G5: =B5+273.15 -> 404.69 | H5: =C5*$K$2*1000 -> 192.78526 | I5: =D5*$K$2*1000 -> 280.49233
A6: 111.06 | B6: 132.04 | C6: 12.08 | D6: 15.71 | F6: =A6*101325 -> 11253154 | G6: =B6+273.15 -> 405.19 | H6: =C6*$K$2*1000 -> 205.72844 | I6: =D6*$K$2*1000 -> 267.54916
A7: 111.55 | B7: 132.25 | C7: 12.81 | D7: 14.84 | F7: =A7*101325 -> 11302804 | G7: =B7+273.15 -> 405.4 | H7: =C7*$K$2*1000 -> 218.16071 | I7: =D7*$K$2*1000 -> 252.73262

Sheet 0376
A1: T(K) | B1: P(bar) | C1: v'(cm3/g) | D1: v''(cm3/g) | F1: P | G1: T | H1: rho_v | I1: rho_l
A2: 200 | B2: 0.08666 | C2: 1.372 | D2: 11140 | F2: =B2*100000 -> 8666 | G2: =A2 -> 200 | H2: =1/D2*0.001*1000000 -> 0.089766607 | I2: =1/C2*0.001*1000000 -> 728.86297
A3: 210 | B3: 0.1779 | C3: 1.394 | D3: 5686.8 | F3: =B3*100000 -> 17790 | G3: =A3 -> 210 | H3: =1/D3*0.001*1000000 -> 0.17584582 | I3: =1/C3*0.001*1000000 -> 717.36011
A4: 220 | B4: 0.3391 | C4: 1.417 | D4: 3445.9 | F4: =B4*100000 -> 33910 | G4: =A4 -> 220 | H4: =1/D4*0.001*1000000 -> 0.29019995 | I4: =1/C4*0.001*1000000 -> 705.7163
A5: 230 | B5: 0.6061 | C5: 1.441 | D5: 1813.9 | F5: =B5*100000 -> 60610 | G5: =A5 -> 230 | H5: =1/D5*0.001*1000000 -> 0.55129831 | I5: =1/C5*0.001*1000000 -> 693.96253
A6: 240 | B6: 1.0258 | C6: 1.467 | D6: 1110 | F6: =B6*100000 -> 102580 | G6: =A6 -> 240 | H6: =1/D6*0.001*1000000 -> 0.9009009 | I6: =1/C6*0.001*1000000 -> 681.66326
A7: 250 | B7: 1.6536 | C7: 1.495 | D7: 709.72 | F7: =B7*100000 -> 165360 | G7: =A7 -> 250 | H7: =1/D7*0.001*1000000 -> 1.4090064 | I7: =1/C7*0.001*1000000 -> 668.89632
A8: 260 | B8: 2.559 | C8: 1.524 | D8: 471.41 | F8: =B8*100000 -> 255900 | G8: =A8 -> 260 | H8: =1/D8*0.001*1000000 -> 2.1212957 | I8: =1/C8*0.001*1000000 -> 656.16798
A9: 270 | B9: 3.819 | C9: 1.556 | D9: 323.2 | F9: =B9*100000 -> 381900 | G9: =A9 -> 270 | H9: =1/D9*0.001*1000000 -> 3.0940594 | I9: =1/C9*0.001*1000000 -> 642.67352
A10: 280 | B10: 5.518 | C10: 1.589 | D10: 227.9 | F10: =B10*100000 -> 551800 | G10: =A10 -> 280 | H10: =1/D10*0.001*1000000 -> 4.3878894 | I10: =1/C10*0.001*1000000 -> 629.32662
A11: 290 | B11: 7.753 | C11: 1.626 | D11: 164.6 | F11: =B11*100000 -> 775300 | G11: =A11 -> 290 | H11: =1/D11*0.001*1000000 -> 6.0753341 | I11: =1/C11*0.001*1000000 -> 615.00615
A12: 300 | B12: 10.624 | C12: 1.667 | D12: 121.3 | F12: =B12*100000 -> 1062400 | G12: =A12 -> 300 | H12: =1/D12*0.001*1000000 -> 8.2440231 | I12: =1/C12*0.001*1000000 -> 599.88002
A13: 310 | B13: 14.249 | C13: 1.711 | D13: 90.71 | F13: =B13*100000 -> 1424900 | G13: =A13 -> 310 | H13: =1/D13*0.001*1000000 -> 11.024143 | I13: =1/C13*0.001*1000000 -> 584.45354
... A23: 405.6 | B23: 113 | C23: 4.255 | D23: 4.255 | F23: =B23*100000 -> 11300000 | G23: =A23 -> 405.6 | H23: =1/D23*0.001*1000000 -> 235.01763 | I23: =1/C23*0.001*1000000 -> 235.01763

Sheet 0385
A1: P(Mpa) | B1: T(K) | D1: P | E1: T | F1: rho_v | G1: rho_l
A2: 2.32546 | B2: 328.425 | D2: =A2*1000000 -> 2325460 | E2: =B2 -> 328.425 | F2: nan | G2: nan
A3: 2.62769 | B3: 333.368 | D3: =A3*1000000 -> 2627690 | E3: =B3 -> 333.368 | F3: nan | G3: nan
A4: 2.95943 | B4: 338.324 | D4: =A4*1000000 -> 2959430 | E4: =B4 -> 338.324 | F4: nan | G4: nan
A5: 3.32273 | B5: 343.296 | D5: =A5*1000000 -> 3322730 | E5: =B5 -> 343.296 | F5: nan | G5: nan
A6: 3.71589 | B6: 348.242 | D6: =A6*1000000 -> 3715890 | E6: =B6 -> 348.242 | F6: nan | G6: nan
A7: 4.13969 | B7: 353.151 | D7: =A7*1000000 -> 4139690 | E7: =B7 -> 353.151 | F7: nan | G7: nan
A8: 4.60754 | B8: 358.148 | D8: =A8*1000000 -> 4607540 | E8: =B8 -> 358.148 | F8: nan | G8: nan
A9: 5.10784 | B9: 363.09 | D9: =A9*1000000 -> 5107840 | E9: =B9 -> 363.09 | F9: nan | G9: nan
A10: 5.68449 | B10: 368.351 | D10: =A10*1000000 -> 5684490 | E10: =B10 -> 368.351 | F10: nan | G10: nan
A11: 6.33329 | B11: 373.806 | D11: =A11*1000000 -> 6333290 | E11: =B11 -> 373.806 | F11: nan | G11: nan
A12: 6.97213 | B12: 378.778 | D12: =A12*1000000 -> 6972130 | E12: =B12 -> 378.778 | F12: nan | G12: nan
A13: 7.65906 | B13: 383.744 | D13: =A13*1000000 -> 7659060 | E13: =B13 -> 383.744 | F13: nan | G13: nan
... A17: 10.97369 | B17: 403.588 | D17: =A17*1000000 -> 10973690 | E17: =B17 -> 403.588 | F17: nan | G17: nan

Sheet 0386
A1: P(mmHg) | B1: T© | D1: P | E1: T | F1: rho_v | G1: rho_l
A2: 760 | B2: 238.5 | D2: =A2*133.322 -> 101324.72 | E2: =B2 -> 238.5 | F2: nan | G2: nan
A3: 730 | B3: 237.7 | D3: =A3*133.322 -> 97325.06 | E3: =B3 -> 237.7 | F3: nan | G3: nan
A4: 700 | B4: 236.8 | D4: =A4*133.322 -> 93325.4 | E4: =B4 -> 236.8 | F4: nan | G4: nan
A5: 650 | B5: 235.4 | D5: =A5*133.322 -> 86659.3 | E5: =B5 -> 235.4 | F5: nan | G5: nan
A6: 600 | B6: 233.8 | D6: =A6*133.322 -> 79993.2 | E6: =B6 -> 233.8 | F6: nan | G6: nan
A7: 500 | B7: 230.7 | D7: =A7*133.322 -> 66661 | E7: =B7 -> 230.7 | F7: nan | G7: nan
A8: 400 | B8: 226.8 | D8: =A8*133.322 -> 53328.8 | E8: =B8 -> 226.8 | F8: nan | G8: nan
A9: 300 | B9: 222.4 | D9: =A9*133.322 -> 39996.6 | E9: =B9 -> 222.4 | F9: nan | G9: nan
A10: 200 | B10: 216.3 | D10: =A10*133.322 -> 26664.4 | E10: =B10 -> 216.3 | F10: nan | G10: nan
A11: 150 | B11: 212.3 | D11: =A11*133.322 -> 19998.3 | E11: =B11 -> 212.3 | F11: nan | G11: nan
A12: 100 | B12: 206.5 | D12: =A12*133.322 -> 13332.2 | E12: =B12 -> 206.5 | F12: nan | G12: nan
A13: 50 | B13: 197 | D13: =A13*133.322 -> 6666.1 | E13: =B13 -> 197 | F13: nan | G13: nan
... A18: 1 | B18: 159.8 | D18: =A18*133.322 -> 133.322 | E18: =B18 -> 159.8 | F18: nan | G18: nan

Sheet 0388
A1: T(K) | B1: P*(kPa) | C1: Pdelta(kPa) | D1: P(kPa) | F1: P | G1: T | H1: rho_v | I1: rho_l
A2: 228.55 | B2: 48.273 | C2: 7.4807 | D2: =C2+B2 -> 55.7537 | F2: =D2*1000 -> 55753.7 | G2: =A2 -> 228.55 | H2: nan | I2: nan
A3: 229.51 | B3: 50.869 | C3: 7.817 | D3: =C3+B3 -> 58.686 | F3: =D3*1000 -> 58686 | G3: =A3 -> 229.51 | H3: nan | I3: nan
A4: 229.94 | B4: 52.235 | C4: 7.9327 | D4: =C4+B4 -> 60.1677 | F4: =D4*1000 -> 60167.7 | G4: =A4 -> 229.94 | H4: nan | I4: nan
A5: 230.38 | B5: 53.662 | C5: 8.1031 | D5: =C5+B5 -> 61.7651 | F5: =D5*1000 -> 61765.1 | G5: =A5 -> 230.38 | H5: nan | I5: nan
A6: 230.47 | B6: 53.885 | C6: 8.1187 | D6: =C6+B6 -> 62.0037 | F6: =D6*1000 -> 62003.7 | G6: =A6 -> 230.47 | H6: nan | I6: nan
A7: 230.98 | B7: 55.417 | C7: 8.3007 | D7: =C7+B7 -> 63.7177 | F7: =D7*1000 -> 63717.7 | G7: =A7 -> 230.98 | H7: nan | I7: nan
A8: 231.07 | B8: 55.739 | C8: 8.31 | D8: =C8+B8 -> 64.049 | F8: =D8*1000 -> 64049 | G8: =A8 -> 231.07 | H8: nan | I8: nan
A9: 231.37 | B9: 56.677 | C9: 8.4433 | D9: =C9+B9 -> 65.1203 | F9: =D9*1000 -> 65120.3 | G9: =A9 -> 231.37 | H9: nan | I9: nan
A10: 231.43 | B10: 56.84 | C10: 8.4486 | D10: =C10+B10 -> 65.2886 | F10: =D10*1000 -> 65288.6 | G10: =A10 -> 231.43 | H10: nan | I10: nan
A11: 231.54 | B11: 57.102 | C11: 8.4913 | D11: =C11+B11 -> 65.5933 | F11: =D11*1000 -> 65593.3 | G11: =A11 -> 231.54 | H11: nan | I11: nan
A12: 231.89 | B12: 58.237 | C12: 8.5833 | D12: =C12+B12 -> 66.8203 | F12: =D12*1000 -> 66820.3 | G12: =A12 -> 231.89 | H12: nan | I12: nan
A13: 232.69 | B13: 61.036 | C13: 8.9099 | D13: =C13+B13 -> 69.9459 | F13: =D13*1000 -> 69945.9 | G13: =A13 -> 232.69 | H13: nan | I13: nan
... A32: 237.92 | B32: 80.809 | C32: 10.9511 | D32: =C32+B32 -> 91.7601 | F32: =D32*1000 -> 91760.1 | G32: =A32 -> 237.92 | H32: nan | I32: nan

Sheet 0389
A1: T© | B1: P(mmHg) | D1: P | E1: T | F1: rho_v | G1: rho_l
A2: -78.44 | B2: 42.2 | D2: =B2*133.322 -> 5626.1884 | E2: =A2+273.15 -> 194.71 | F2: nan | G2: nan
A3: -78.45 | B3: 42.8 | D3: =B3*133.322 -> 5706.1816 | E3: =A3+273.15 -> 194.7 | F3: nan | G3: nan
A4: -77.7 | B4: 44.9 | D4: =B4*133.322 -> 5986.1578 | E4: =A4+273.15 -> 195.45 | F4: nan | G4: nan
A5: -64.5 | B5: 121.2 | D5: =B5*133.322 -> 16158.626 | E5: =A5+273.15 -> 208.65 | F5: nan | G5: nan
A6: -64.27 | B6: 122.8 | D6: =B6*133.322 -> 16371.942 | E6: =A6+273.15 -> 208.88 | F6: nan | G6: nan
A7: -53.036 | B7: 256.3 | D7: =B7*133.322 -> 34170.429 | E7: =A7+273.15 -> 220.114 | F7: nan | G7: nan
A8: -51.76 | B8: 276.6 | D8: =B8*133.322 -> 36876.865 | E8: =A8+273.15 -> 221.39 | F8: nan | G8: nan
A9: -51.603 | B9: 278.9 | D9: =B9*133.322 -> 37183.506 | E9: =A9+273.15 -> 221.547 | F9: nan | G9: nan
A10: -50.717 | B10: 294.5 | D10: =B10*133.322 -> 39263.329 | E10: =A10+273.15 -> 222.433 | F10: nan | G10: nan
A11: =-50.717 -> -50.717 | B11: 294.4 | D11: =B11*133.322 -> 39249.997 | E11: =A11+273.15 -> 222.433 | F11: nan | G11: nan
A12: -48.495 | B12: 335.2 | D12: =B12*133.322 -> 44689.534 | E12: =A12+273.15 -> 224.655 | F12: nan | G12: nan
A13: -48.172 | B13: 341.9 | D13: =B13*133.322 -> 45582.792 | E13: =A13+273.15 -> 224.978 | F13: nan | G13: nan
A14: -47.781 | B14: 349.5 | D14: =B14*133.322 -> 46596.039 | E14: =A14+273.15 -> 225.369 | F14: nan | G14: nan
A15: -47.62 | B15: 352.3 | D15: =B15*133.322 -> 46969.341 | E15: =A15+273.15 -> 225.53 | F15: nan | G15: nan
A16: -45.946 | B16: 388.3 | D16: =B16*133.322 -> 51768.933 | E16: =A16+273.15 -> 227.204 | F16: nan | G16: nan
A17: -44.597 | B17: 419 | D17: =B17*133.322 -> 55861.918 | E17: =A17+273.15 -> 228.553 | F17: nan | G17: nan
A18: -44.27 | B18: 426.2 | D18: =B18*133.322 -> 56821.836 | E18: =A18+273.15 -> 228.88 | F18: nan | G18: nan
A19: -44.169 | B19: 428.6 | D19: =B19*133.322 -> 57141.809 | E19: =A19+273.15 -> 228.981 | F19: nan | G19: nan
A20: -44.059 | B20: 431.9 | D20: =B20*133.322 -> 57581.772 | E20: =A20+273.15 -> 229.091 | F20: nan | G20: nan
A21: -44.034 | B21: 432.4 | D21: =B21*133.322 -> 57648.433 | E21: =A21+273.15 -> 229.116 | F21: nan | G21: nan
A22: -43.937 | B22: 434.3 | D22: =B22*133.322 -> 57901.745 | E22: =A22+273.15 -> 229.213 | F22: nan | G22: nan
A23: -43.423 | B23: 446.9 | D23: =B23*133.322 -> 59581.602 | E23: =A23+273.15 -> 229.727 | F23: nan | G23: nan
... A99: -33.25 | B99: 763.7 | D99: =B99*133.322 -> 101818.01 | E99: =A99+273.15 -> 239.9 | F99: nan | G99: nan
A100: =-33.244 -> -33.244 | B100: 763.6 | D100: =B100*133.322 -> 101804.68 | E100: =A100+273.15 -> 239.906 | F100: nan | G100: nan
A101: -33.243 | B101: 764.3 | D101: =B101*133.322 -> 101898 | E101: =A101+273.15 -> 239.907 | F101: nan | G101: nan
A102: -33.241 | B102: 764.5 | D102: =B102*133.322 -> 101924.67 | E102: =A102+273.15 -> 239.909 | F102: nan | G102: nan
A103: -33.123 | B103: 768.9 | D103: =B103*133.322 -> 102511.29 | E103: =A103+273.15 -> 240.027 | F103: nan | G103: nan
A104: -30.45 | B104: 877.4 | D104: =B104*133.322 -> 116976.72 | E104: =A104+273.15 -> 242.7 | F104: nan | G104: nan
A105: -30.081 | B105: 893.3 | D105: =B105*133.322 -> 119096.54 | E105: =A105+273.15 -> 243.069 | F105: nan | G105: nan
A106: -30.038 | B106: 895.8 | D106: =B106*133.322 -> 119429.85 | E106: =A106+273.15 -> 243.112 | F106: nan | G106: nan
A107: -30.011 | B107: 897.1 | D107: =B107*133.322 -> 119603.17 | E107: =A107+273.15 -> 243.139 | F107: nan | G107: nan
A108: -30.004 | B108: 896.9 | D108: =B108*133.322 -> 119576.5 | E108: =A108+273.15 -> 243.146 | F108: nan | G108: nan
A109: -29.913 | B109: 900.7 | D109: =B109*133.322 -> 120083.13 | E109: =A109+273.15 -> 243.237 | F109: nan | G109: nan
A110: -25.059 | B110: 1134.2 | D110: =B110*133.322 -> 151213.81 | E110: =A110+273.15 -> 248.091 | F110: nan | G110: nan
A111: -25.05 | B111: 1134.7 | D111: =B111*133.322 -> 151280.47 | E111: =A111+273.15 -> 248.1 | F111: nan | G111: nan
A112: -25.035 | B112: 1136 | D112: =B112*133.322 -> 151453.79 | E112: =A112+273.15 -> 248.115 | F112: nan | G112: nan
... A151: 70.011 | B151: 24842.6 | D151: =B151*133.322 -> 3312065.1 | E151: =A151+273.15 -> 343.161 | F151: nan | G151: nan
