Workbook

Sheet Sheet1
A1: Paper | B1: table or figure or page | C1: P | D1: T | E1: rho | G1: P
A2: 357 | B2: 2 | C2: ='0357 table 2'!E2 -> 2998206.8 | D2: ='0357 table 2'!F2 -> 598.15 | E2: ='0357 table 2'!G2 -> 10.526316 | G2: 2998206.8
A3: 357 | B3: 2 | C3: ='0357 table 2'!E3 -> 3163366.5 | D3: ='0357 table 2'!F3 -> 598.15 | E3: ='0357 table 2'!G3 -> 11.111111 | G3: 3163366.5
A4: 357 | B4: 2 | C4: ='0357 table 2'!E4 -> 3550428 | D4: ='0357 table 2'!F4 -> 598.15 | E4: ='0357 table 2'!G4 -> 12.5 | G4: 3550428
A5: 357 | B5: 2 | C5: ='0357 table 2'!E5 -> 4042867.5 | D5: ='0357 table 2'!F5 -> 598.15 | E5: ='0357 table 2'!G5 -> 14.285714 | G5: 4042867.5
A6: 357 | B6: 2 | C6: ='0357 table 2'!E6 -> 4695400.5 | D6: ='0357 table 2'!F6 -> 598.15 | E6: ='0357 table 2'!G6 -> 16.666667 | G6: 4695400.5
A7: 357 | B7: 2 | C7: ='0357 table 2'!E7 -> 5597193 | D7: ='0357 table 2'!F7 -> 598.15 | E7: ='0357 table 2'!G7 -> 20 | G7: 5597193
A8: 357 | B8: 2 | C8: ='0357 table 2'!E8 -> 6191970.8 | D8: ='0357 table 2'!F8 -> 598.15 | E8: ='0357 table 2'!G8 -> 22.222222 | G8: 6191970.8
A9: 357 | B9: 2 | C9: ='0357 table 2'!E9 -> 6926577 | D9: ='0357 table 2'!F9 -> 598.15 | E9: ='0357 table 2'!G9 -> 25 | G9: 6926577
A10: 357 | B10: 2 | C10: ='0357 table 2'!E10 -> 7861806.8 | D10: ='0357 table 2'!F10 -> 598.15 | E10: ='0357 table 2'!G10 -> 28.571429 | G10: 7861806.8
A11: 357 | B11: 2 | C11: ='0357 table 2'!E11 -> 9087839.2 | D11: ='0357 table 2'!F11 -> 598.15 | E11: ='0357 table 2'!G11 -> 33.333333 | G11: 9087839.2
A12: 357 | B12: 2 | C12: ='0357 table 2'!E12 -> 10765781 | D12: ='0357 table 2'!F12 -> 598.15 | E12: ='0357 table 2'!G12 -> 40 | G12: 10765781
A13: 357 | B13: 2 | C13: ='0357 table 2'!E13 -> 13212780 | D13: ='0357 table 2'!F13 -> 598.15 | E13: ='0357 table 2'!G13 -> 50 | G13: 13212780
... A189: 357 | B189: 2 | C189: ='0357 table 2'!E189 -> 87646.125 | D189: ='0357 table 2'!F189 -> 238.15 | E189: ='0357 table 2'!G189 -> 0.76923077 | G189: 87646.125
A190: 358 | B190: 1 | C190: ='0358 table 1'!E2 -> 202650 | D190: ='0358 table 1'!F2 -> 298.15 | E190: ='0358 table 1'!G2 -> 1.4235301 | G190: 303975
A191: 358 | B191: 1 | C191: ='0358 table 1'!E3 -> 405300 | D191: ='0358 table 1'!F3 -> 298.15 | E191: ='0358 table 1'!G3 -> 2.9168499 | G191: 506625
A192: 358 | B192: 1 | C192: ='0358 table 1'!E4 -> 607950 | D192: ='0358 table 1'!F4 -> 298.15 | E192: ='0358 table 1'!G4 -> 4.487148 | G192: 709275
A193: 358 | B193: 1 | C193: ='0358 table 1'!E5 -> 709275 | D193: ='0358 table 1'!F5 -> 298.15 | E193: ='0358 table 1'!G5 -> 5.3132086 | G193: 810600
A194: 358 | B194: 1 | C194: ='0358 table 1'!E6 -> 810600 | D194: ='0358 table 1'!F6 -> 298.15 | E194: ='0358 table 1'!G6 -> 6.1691036 | G194: 911925
A195: 358 | B195: 1 | C195: ='0358 table 1'!E7 -> 911925 | D195: ='0358 table 1'!F7 -> 298.15 | E195: ='0358 table 1'!G7 -> 7.0694607 | G195: 1013250
A196: 358 | B196: 1 | C196: ='0358 table 1'!E8 -> 942322.5 | D196: ='0358 table 1'!F8 -> 298.15 | E196: ='0358 table 1'!G8 -> 7.3565772 | G196: 1043647.5
A197: 358 | B197: 1 | C197: ='0358 table 1'!E9 -> 962587.5 | D197: ='0358 table 1'!F9 -> 298.15 | E197: ='0358 table 1'!G9 -> 7.5637758 | G197: 1063912.5
A198: 358 | B198: 1 | C198: ='0358 table 1'!E10 -> 982852.5 | D198: ='0358 table 1'!F10 -> 298.15 | E198: ='0358 table 1'!G10 -> 7.8006359 | G198: 1084177.5
A199: 358 | B199: 1 | C199: ='0358 table 1'!E11 -> 202650 | D199: ='0358 table 1'!F11 -> 323.15 | E199: ='0358 table 1'!G11 -> 1.3032732 | G199: 303975
A200: 358 | B200: 1 | C200: ='0358 table 1'!E12 -> 405300 | D200: ='0358 table 1'!F12 -> 323.15 | E200: ='0358 table 1'!G12 -> 2.6473745 | G200: 506625
A201: 358 | B201: 1 | C201: ='0358 table 1'!E13 -> 607950 | D201: ='0358 table 1'!F13 -> 323.15 | E201: ='0358 table 1'!G13 -> 4.0376344 | G201: 709275
... A248: 358 | B248: 1 | C248: ='0358 table 1'!E60 -> 9625875 | D248: ='0358 table 1'!F60 -> 398.15 | E248: ='0358 table 1'!G60 -> 104.91685 | G248: 9727200
A249: 358 | B249: 2 | C249: ='0358 table 2'!E2 -> 469861.52 | D249: ='0358 table 2'!F2 -> 298.15 | E249: ='0358 table 2'!G2 -> 3.406104 | G249: 106916.75
A250: 358 | B250: 2 | C250: ='0358 table 2'!E3 -> 885086.82 | D250: ='0358 table 2'!F3 -> 298.15 | E250: ='0358 table 2'!G3 -> 6.812208 | G250: 113516.69
A251: 358 | B251: 2 | C251: ='0358 table 2'!E4 -> 972184.97 | D251: ='0358 table 2'!F4 -> 298.15 | E251: ='0358 table 2'!G4 -> 7.663734 | G251: 116265.06
A252: 358 | B252: 2 | C252: ='0358 table 2'!E5 -> 1007696 | D252: ='0358 table 2'!F5 -> 298.15 | E252: ='0358 table 2'!G5 -> 8.51526 | G252: 124631
A253: 358 | B253: 2 | C253: ='0358 table 2'!E6 -> 515600.49 | D253: ='0358 table 2'!F6 -> 323.15 | E253: ='0358 table 2'!G6 -> 3.406104 | G253: 105601.88
A254: 358 | B254: 2 | C254: ='0358 table 2'!E7 -> 988211.88 | D254: ='0358 table 2'!F7 -> 323.15 | E254: ='0358 table 2'!G7 -> 6.812208 | G254: 110195.76
A255: 358 | B255: 2 | C255: ='0358 table 2'!E8 -> 1207993.6 | D255: ='0358 table 2'!F8 -> 323.15 | E255: ='0358 table 2'!G8 -> 8.51526 | G255: 112683.5
A256: 358 | B256: 2 | C256: ='0358 table 2'!E9 -> 1418317.8 | D256: ='0358 table 2'!F9 -> 323.15 | E256: ='0358 table 2'!G9 -> 10.218312 | G256: 115168.22
A257: 358 | B257: 2 | C257: ='0358 table 2'!E10 -> 1618029 | D257: ='0358 table 2'!F10 -> 323.15 | E257: ='0358 table 2'!G10 -> 11.921364 | G257: 117778.68
A258: 358 | B258: 2 | C258: ='0358 table 2'!E11 -> 1804037.5 | D258: ='0358 table 2'!F11 -> 323.15 | E258: ='0358 table 2'!G11 -> 13.624416 | G258: 120725.6
A259: 358 | B259: 2 | C259: ='0358 table 2'!E12 -> 1889841 | D259: ='0358 table 2'!F12 -> 323.15 | E259: ='0358 table 2'!G12 -> 14.475942 | G259: 122447.13
A260: 358 | B260: 2 | C260: ='0358 table 2'!E13 -> 1968363.3 | D260: ='0358 table 2'!F13 -> 323.15 | E260: ='0358 table 2'!G13 -> 15.327468 | G260: 124477.89
... A299: 358 | B299: 2 | C299: ='0358 table 2'!E52 -> 9557796.4 | D299: ='0358 table 2'!F52 -> 398.15 | E299: ='0358 table 2'!G52 -> 102.18312 | G299: 210567.33
...

Sheet 0377 table 1
A1: P (kg/cm2) | B1: T © | C1: v (cm3/g) | E1: P (Pa) | F1: T (K) | G1: rho (kg/m3)
A2: 0.8935 | B2: -35 | C2: 1300 | E2: =A2*9.81*10000 -> 87652.35 | F2: =B2+273.15 -> 238.15 | G2: =1/C2*0.001*1000000 -> 0.76923077
A3: 0.911 | B3: -30 | C3: 1300 | E3: =A3*9.81*10000 -> 89369.1 | F3: =B3+273.15 -> 243.15 | G3: =1/C3*0.001*1000000 -> 0.76923077
A4: 0.9512 | B4: -20 | C4: 1300 | E4: =A4*9.81*10000 -> 93312.72 | F4: =B4+273.15 -> 253.15 | G4: =1/C4*0.001*1000000 -> 0.76923077
A5: 1.0305 | B5: 0 | C5: 1300 | E5: =A5*9.81*10000 -> 101092.05 | F5: =B5+273.15 -> 273.15 | G5: =1/C5*0.001*1000000 -> 0.76923077
A6: 1.1288 | B6: 25 | C6: 1300 | E6: =A6*9.81*10000 -> 110735.28 | F6: =B6+273.15 -> 298.15 | G6: =1/C6*0.001*1000000 -> 0.76923077
A7: 1.2263 | B7: 50 | C7: 1300 | E7: =A7*9.81*10000 -> 120300.03 | F7: =B7+273.15 -> 323.15 | G7: =1/C7*0.001*1000000 -> 0.76923077
A8: 1.4199 | B8: 100 | C8: 1300 | E8: =A8*9.81*10000 -> 139292.19 | F8: =B8+273.15 -> 373.15 | G8: =1/C8*0.001*1000000 -> 0.76923077
A9: 1.6128 | B9: 150 | C9: 1300 | E9: =A9*9.81*10000 -> 158215.68 | F9: =B9+273.15 -> 423.15 | G9: =1/C9*0.001*1000000 -> 0.76923077
A10: 1.805 | B10: 200 | C10: 1300 | E10: =A10*9.81*10000 -> 177070.5 | F10: =B10+273.15 -> 473.15 | G10: =1/C10*0.001*1000000 -> 0.76923077
A11: 2.5017 | B11: -10 | C11: 500 | E11: =A11*9.81*10000 -> 245416.77 | F11: =B11+273.15 -> 263.15 | G11: =1/C11*0.001*1000000 -> 2
A12: 2.6116 | B12: 0 | C12: 500 | E12: =A12*9.81*10000 -> 256197.96 | F12: =B12+273.15 -> 273.15 | G12: =1/C12*0.001*1000000 -> 2
A13: 2.8788 | B13: 25 | C13: 500 | E13: =A13*9.81*10000 -> 282410.28 | F13: =B13+273.15 -> 298.15 | G13: =1/C13*0.001*1000000 -> 2
... A56: 29.322 | B56: 250 | C56: 85.5 | E56: =A56*9.81*10000 -> 2876488.2 | F56: =B56+273.15 -> 523.15 | G56: =1/C56*0.001*1000000 -> 11.695906

Sheet 0376 page 464
A1: P (bar) | B1: T (K) | C1: v (cm3/g) | E1: P (Pa) | F1: T (K) | G1: rho (kg/m3)
A2: 1 | B2: 300 | C2: 1450.6 | E2: =A2*100000 -> 100000 | F2: =B2 -> 300 | G2: =1/C2*0.001*1000000 -> 0.68936992
A3: 1 | B3: 320 | C3: 1550.8 | E3: =A3*100000 -> 100000 | F3: =B3 -> 320 | G3: =1/C3*0.001*1000000 -> 0.64482848
A4: 1 | B4: 340 | C4: 1650.5 | E4: =A4*100000 -> 100000 | F4: =B4 -> 340 | G4: =1/C4*0.001*1000000 -> 0.60587701
A5: 1 | B5: 360 | C5: 1749.6 | E5: =A5*100000 -> 100000 | F5: =B5 -> 360 | G5: =1/C5*0.001*1000000 -> 0.57155921
A6: 1 | B6: 380 | C6: 1848.5 | E6: =A6*100000 -> 100000 | F6: =B6 -> 380 | G6: =1/C6*0.001*1000000 -> 0.54097917
A7: 1 | B7: 400 | C7: 1947.2 | E7: =A7*100000 -> 100000 | F7: =B7 -> 400 | G7: =1/C7*0.001*1000000 -> 0.51355793
A8: 1 | B8: 420 | C8: 2045.7 | E8: =A8*100000 -> 100000 | F8: =B8 -> 420 | G8: =1/C8*0.001*1000000 -> 0.48883023
A9: 1 | B9: 440 | C9: 2144.1 | E9: =A9*100000 -> 100000 | F9: =B9 -> 440 | G9: =1/C9*0.001*1000000 -> 0.46639616
A10: 1 | B10: 460 | C10: 2242.3 | E10: =A10*100000 -> 100000 | F10: =B10 -> 460 | G10: =1/C10*0.001*1000000 -> 0.44597066
A11: 1 | B11: 480 | C11: 2340.5 | E11: =A11*100000 -> 100000 | F11: =B11 -> 480 | G11: =1/C11*0.001*1000000 -> 0.42725913
A12: 1 | B12: 500 | C12: 2438.6 | E12: =A12*100000 -> 100000 | F12: =B12 -> 500 | G12: =1/C12*0.001*1000000 -> 0.41007135
A13: 1 | B13: 520 | C13: 2536.6 | E13: =A13*100000 -> 100000 | F13: =B13 -> 520 | G13: =1/C13*0.001*1000000 -> 0.39422849
... A662: 1100 | B662: 560 | C662: 2.38 | E662: =A662*100000 -> 110000000 | F662: =B662 -> 560 | G662: =1/C662*0.001*1000000 -> 420.16807

Sheet 0374 table 5
A1: P (lbs/in2) | B1: T (F) | C1: v (ft3/lb) | E1: P (Pa) | F1: T(K) | G1: rho(kg/m3)
A2: 5 | B2: -50 | C2: 51.05 | E2: =A2*6894.76 -> 34473.8 | F2: =(B2-32)*5/9+273.15 -> 227.59444 | G2: =1/(C2*0.062428) -> 0.31377969
A3: 5 | B3: -40 | C3: 52.36 | E3: =A3*6894.76 -> 34473.8 | F3: =(B3-32)*5/9+273.15 -> 233.15 | G3: =1/(C3*0.062428) -> 0.30592921
A4: 5 | B4: -30 | C4: 53.67 | E4: =A4*6894.76 -> 34473.8 | F4: =(B4-32)*5/9+273.15 -> 238.70556 | G4: =1/(C4*0.062428) -> 0.29846196
A5: 5 | B5: -20 | C5: 54.97 | E5: =A5*6894.76 -> 34473.8 | F5: =(B5-32)*5/9+273.15 -> 244.26111 | G5: =1/(C5*0.062428) -> 0.29140355
A6: 5 | B6: -10 | C6: 56.26 | E6: =A6*6894.76 -> 34473.8 | F6: =(B6-32)*5/9+273.15 -> 249.81667 | G6: =1/(C6*0.062428) -> 0.28472189
A7: 5 | B7: 0 | C7: 57.55 | E7: =A7*6894.76 -> 34473.8 | F7: =(B7-32)*5/9+273.15 -> 255.37222 | G7: =1/(C7*0.062428) -> 0.27833976
A8: 5 | B8: 10 | C8: 58.84 | E8: =A8*6894.76 -> 34473.8 | F8: =(B8-32)*5/9+273.15 -> 260.92778 | G8: =1/(C8*0.062428) -> 0.27223748
A9: 5 | B9: 20 | C9: 60.12 | E9: =A9*6894.76 -> 34473.8 | F9: =(B9-32)*5/9+273.15 -> 266.48333 | G9: =1/(C9*0.062428) -> 0.26644134
A10: 5 | B10: 30 | C10: 61.41 | E10: =A10*6894.76 -> 34473.8 | F10: =(B10-32)*5/9+273.15 -> 272.03889 | G10: =1/(C10*0.062428) -> 0.26084438
A11: 5 | B11: 40 | C11: 62.69 | E11: =A11*6894.76 -> 34473.8 | F11: =(B11-32)*5/9+273.15 -> 277.59444 | G11: =1/(C11*0.062428) -> 0.25551848
A12: 5 | B12: 50 | C12: 63.96 | E12: =A12*6894.76 -> 34473.8 | F12: =(B12-32)*5/9+273.15 -> 283.15 | G12: =1/(C12*0.062428) -> 0.25044486
A13: 5 | B13: 60 | C13: 65.24 | E13: =A13*6894.76 -> 34473.8 | F13: =(B13-32)*5/9+273.15 -> 288.70556 | G13: =1/(C13*0.062428) -> 0.24553117
... A1983: 300 | B1983: 400 | C1983: 1.732 | E1983: =A1983*6894.76 -> 2068428 | F1983: =(B1983-32)*5/9+273.15 -> 477.59444 | G1983: =1/(C1983*0.062428) -> 9.2485296

Sheet 0373 table 4
A1: P (Mpa) | B1: T (K) | C1: rho (g/cm3) | E1: P | F1: T | G1: rho
A2: 50 | B2: 298 | C2: 0.6426 | E2: =A2*1000000 -> 50000000 | F2: =B2 -> 298 | G2: =C2*0.001*1000000 -> 642.6
A3: 100 | B3: 298 | C3: 0.669 | E3: =A3*1000000 -> 100000000 | F3: =B3 -> 298 | G3: =C3*0.001*1000000 -> 669
A4: 150 | B4: 298 | C4: 0.6898 | E4: =A4*1000000 -> 150000000 | F4: =B4 -> 298 | G4: =C4*0.001*1000000 -> 689.8
A5: 200 | B5: 298 | C5: 0.7072 | E5: =A5*1000000 -> 200000000 | F5: =B5 -> 298 | G5: =C5*0.001*1000000 -> 707.2
A6: 300 | B6: 298 | C6: 0.7357 | E6: =A6*1000000 -> 300000000 | F6: =B6 -> 298 | G6: =C6*0.001*1000000 -> 735.7
A7: 400 | B7: 298 | C7: 0.7581 | E7: =A7*1000000 -> 400000000 | F7: =B7 -> 298 | G7: =C7*0.001*1000000 -> 758.1
A8: 500 | B8: 298 | C8: 0.7761 | E8: =A8*1000000 -> 500000000 | F8: =B8 -> 298 | G8: =C8*0.001*1000000 -> 776.1
A9: 600 | B9: 298 | C9: 0.7914 | E9: =A9*1000000 -> 600000000 | F9: =B9 -> 298 | G9: =C9*0.001*1000000 -> 791.4
A10: 700 | B10: 298 | C10: 0.804 | E10: =A10*1000000 -> 700000000 | F10: =B10 -> 298 | G10: =C10*0.001*1000000 -> 804
A11: 800 | B11: 298 | C11: 0.8148 | E11: =A11*1000000 -> 800000000 | F11: =B11 -> 298 | G11: =C11*0.001*1000000 -> 814.8
A12: 900 | B12: 298 | C12: 0.8259 | E12: =A12*1000000 -> 900000000 | F12: =B12 -> 298 | G12: =C12*0.001*1000000 -> 825.9
A13: 950 | B13: 298 | C13: 0.8287 | E13: =A13*1000000 -> 950000000 | F13: =B13 -> 298 | G13: =C13*0.001*1000000 -> 828.7
... A99: 800 | B99: 723 | C99: 0.6579 | E99: =A99*1000000 -> 800000000 | F99: =B99 -> 723 | G99: =C99*0.001*1000000 -> 657.9

Sheet 0372 table 1
A1: rho (g/cm3) | B1: T © | C1: P (bar) | E1: P (Pa) | F1: T (K) | G1: rho (kg/m3)
A2: 0.5796 | B2: 44.75 | C2: 84.294 | E2: =C2*100000 -> 8429400 | F2: =B2+273.15 -> 317.9 | G2: =A2*0.001*1000000 -> 579.6
A3: 0.5794 | B3: 50.58 | C3: 163.233 | E3: =C3*100000 -> 16323300 | F3: =B3+273.15 -> 323.73 | G3: =A3*0.001*1000000 -> 579.4
A4: 0.5794 | B4: 50.61 | C4: 163.512 | E4: =C4*100000 -> 16351200 | F4: =B4+273.15 -> 323.76 | G4: =A4*0.001*1000000 -> 579.4
A5: 0.5792 | B5: 55.3 | C5: 226.709 | E5: =C5*100000 -> 22670900 | F5: =B5+273.15 -> 328.45 | G5: =A5*0.001*1000000 -> 579.2
A6: 0.579 | B6: 60.02 | C6: 289.569 | E6: =C6*100000 -> 28956900 | F6: =B6+273.15 -> 333.17 | G6: =A6*0.001*1000000 -> 579
A7: 0.5788 | B7: 64.63 | C7: 352.278 | E7: =C7*100000 -> 35227800 | F7: =B7+273.15 -> 337.78 | G7: =A7*0.001*1000000 -> 578.8
A8: 0.6197 | B8: 15.29 | C8: 45.25 | E8: =C8*100000 -> 4525000 | F8: =B8+273.15 -> 288.44 | G8: =A8*0.001*1000000 -> 619.7
A9: 0.6195 | B9: 20.48 | C9: 131.448 | E9: =C9*100000 -> 13144800 | F9: =B9+273.15 -> 293.63 | G9: =A9*0.001*1000000 -> 619.5
A10: 0.6192 | B10: 25.39 | C10: 212.84 | E10: =C10*100000 -> 21284000 | F10: =B10+273.15 -> 298.54 | G10: =A10*0.001*1000000 -> 619.2
A11: 0.619 | B11: 30.14 | C11: 291.268 | E11: =C11*100000 -> 29126800 | F11: =B11+273.15 -> 303.29 | G11: =A11*0.001*1000000 -> 619
A12: 0.619 | B12: 30.47 | C12: 296.947 | E12: =C12*100000 -> 29694700 | F12: =B12+273.15 -> 303.62 | G12: =A12*0.001*1000000 -> 619
A13: 0.619 | B13: 30.48 | C13: 296.719 | E13: =C13*100000 -> 29671900 | F13: =B13+273.15 -> 303.63 | G13: =A13*0.001*1000000 -> 619
... A23: 0.7024 | B23: -37.8 | C23: 339.028 | E23: =C23*100000 -> 33902800 | F23: =B23+273.15 -> 235.35 | G23: =A23*0.001*1000000 -> 702.4

Sheet 0371 table 2
A1: T (K) | B1: P (kPa) | C1: rho (cm3/mol) | E1: P | F1: T | G1: rho | I1: M_NH3
A2: 195.48 | B2: 6.079 | C2: 23.205 | E2: =B2*1000 -> 6079 | F2: =A2 -> 195.48 | G2: =1/C2*$I$2*1000000 -> 733.91597 | I2: 0.01703052
A3: 198.84 | B3: 7.915 | C3: 23.331 | E3: =B3*1000 -> 7915 | F3: =A3 -> 198.84 | G3: =1/C3*$I$2*1000000 -> 729.95242
A4: 200 | B4: 8.649 | C4: 23.374 | E4: =B4*1000 -> 8649 | F4: =A4 -> 200 | G4: =1/C4*$I$2*1000000 -> 728.60957
A5: 210 | B5: 17.749 | C5: 23.753 | E5: =B5*1000 -> 17749 | F5: =A5 -> 210 | G5: =1/C5*$I$2*1000000 -> 716.98396
A6: 220 | B6: 33.814 | C6: 24.141 | E6: =B6*1000 -> 33814 | F6: =A6 -> 220 | G6: =1/C6*$I$2*1000000 -> 705.46042
A7: 230 | B7: 60.442 | C7: 24.547 | E7: =B7*1000 -> 60442 | F7: =A7 -> 230 | G7: =1/C7*$I$2*1000000 -> 693.79232
A8: 239.82 | B8: 101.324 | C8: 24.969 | E8: =B8*1000 -> 101324 | F8: =A8 -> 239.82 | G8: =1/C8*$I$2*1000000 -> 682.06656
A9: 240 | B9: 102.263 | C9: 24.977 | E9: =B9*1000 -> 102263 | F9: =A9 -> 240 | G9: =1/C9*$I$2*1000000 -> 681.8481
A10: 241.96 | B10: 112.71 | C10: 25.065 | E10: =B10*1000 -> 112710 | F10: =A10 -> 241.96 | G10: =1/C10*$I$2*1000000 -> 679.45422
A11: 250 | B11: 164.97 | C11: 25.438 | E11: =B11*1000 -> 164970 | F11: =A11 -> 250 | G11: =1/C11*$I$2*1000000 -> 669.49131
A12: 260 | B12: 255.311 | C12: 25.937 | E12: =B12*1000 -> 255311 | F12: =A12 -> 260 | G12: =1/C12*$I$2*1000000 -> 656.61102
A13: 270 | B13: 381.038 | C13: 26.481 | E13: =B13*1000 -> 381038 | F13: =A13 -> 270 | G13: =1/C13*$I$2*1000000 -> 643.12224
A14: 280 | B14: 550.829 | C14: 27.077 | E14: =B14*1000 -> 550829 | F14: =A14 -> 280 | G14: =1/C14*$I$2*1000000 -> 628.96628
A15: 290 | B15: 774.209 | C15: 27.731 | E15: =B15*1000 -> 774209 | F15: =A15 -> 290 | G15: =1/C15*$I$2*1000000 -> 614.13292

Sheet 0370 table 2
A1: P (Mpa) | B1: T (K) | C1: rho (kg/m3) | E1: P | F1: T | G1: rho
A2: 11.3513 | B2: 405.55 | C2: 235.01 | E2: =A2*1000000 -> 11351300 | F2: =B2 -> 405.55 | G2: =C2 -> 235.01
A3: 11.3549 | B3: 405.55 | C3: 249.99 | E3: =A3*1000000 -> 11354900 | F3: =B3 -> 405.55 | G3: =C3 -> 249.99
A4: 11.3589 | B4: 405.55 | C4: 255.19 | E4: =A4*1000000 -> 11358900 | F4: =B4 -> 405.55 | G4: =C4 -> 255.19
A5: 11.3558 | B5: 405.56 | C5: 241.93 | E5: =A5*1000000 -> 11355800 | F5: =B5 -> 405.56 | G5: =C5 -> 241.93
A6: 11.3553 | B6: 405.56 | C6: 242.91 | E6: =A6*1000000 -> 11355300 | F6: =B6 -> 405.56 | G6: =C6 -> 242.91
A7: 11.3592 | B7: 405.56 | C7: 244 | E7: =A7*1000000 -> 11359200 | F7: =B7 -> 405.56 | G7: =C7 -> 244
A8: 11.355 | B8: 405.56 | C8: 244.06 | E8: =A8*1000000 -> 11355000 | F8: =B8 -> 405.56 | G8: =C8 -> 244.06
A9: 11.3575 | B9: 405.56 | C9: 244.95 | E9: =A9*1000000 -> 11357500 | F9: =B9 -> 405.56 | G9: =C9 -> 244.95
A10: 11.3562 | B10: 405.565 | C10: 242.97 | E10: =A10*1000000 -> 11356200 | F10: =B10 -> 405.565 | G10: =C10 -> 242.97
A11: 11.358 | B11: 405.565 | C11: 243.49 | E11: =A11*1000000 -> 11358000 | F11: =B11 -> 405.565 | G11: =C11 -> 243.49
A12: 11.3574 | B12: 405.565 | C12: 244.01 | E12: =A12*1000000 -> 11357400 | F12: =B12 -> 405.565 | G12: =C12 -> 244.01
A13: 11.3601 | B13: 405.57 | C13: 241.94 | E13: =A13*1000000 -> 11360100 | F13: =B13 -> 405.57 | G13: =C13 -> 241.94
... A27: 11.3672 | B27: 405.6 | C27: 245.12 | E27: =A27*1000000 -> 11367200 | F27: =B27 -> 405.6 | G27: =C27 -> 245.12

Sheet 0369
A1: P (atm) | B1: T © | C1: rho (g/L) | E1: P | F1: T | G1: rho
A2: 1 | B2: 0 | C2: 0.77085 | E2: =A2*101325 -> 101325 | F2: =B2+273.15 -> 273.15 | G2: =C2*0.001*1000 -> 0.77085
A3: 1 | B3: 50 | C3: 0.64627 | E3: =A3*101325 -> 101325 | F3: =B3+273.15 -> 323.15 | G3: =C3*0.001*1000 -> 0.64627
A4: 1 | B4: 100 | C4: 0.55668 | E4: =A4*101325 -> 101325 | F4: =B4+273.15 -> 373.15 | G4: =C4*0.001*1000 -> 0.55668
A5: 1 | B5: -20 | C5: 0.8363 | E5: =A5*101325 -> 101325 | F5: =B5+273.15 -> 253.15 | G5: =C5*0.001*1000 -> 0.8363
A6: 0.5 | B6: 0 | C6: 0.3832 | E6: =A6*101325 -> 50662.5 | F6: =B6+273.15 -> 273.15 | G6: =C6*0.001*1000 -> 0.3832

Sheet 0368 table 1
A1: P (Mpa) | B1: T (K) | C1: rho (kg/m3) | E1: p | F1: T | G1: rho
A2: 200 | B2: 450 | C2: 588.2 | E2: =A2*1000000 -> 200000000 | F2: =B2 -> 450 | G2: =C2 -> 588.2
A3: 180 | B3: 450 | C3: 576.3 | E3: =A3*1000000 -> 180000000 | F3: =B3 -> 450 | G3: =C3 -> 576.3
A4: 160 | B4: 450 | C4: 563.1 | E4: =A4*1000000 -> 160000000 | F4: =B4 -> 450 | G4: =C4 -> 563.1
A5: 140 | B5: 450 | C5: 548.2 | E5: =A5*1000000 -> 140000000 | F5: =B5 -> 450 | G5: =C5 -> 548.2
A6: 120 | B6: 450 | C6: 531.4 | E6: =A6*1000000 -> 120000000 | F6: =B6 -> 450 | G6: =C6 -> 531.4
A7: 100 | B7: 450 | C7: 511.7 | E7: =A7*1000000 -> 100000000 | F7: =B7 -> 450 | G7: =C7 -> 511.7
A8: 90 | B8: 450 | C8: 500.2 | E8: =A8*1000000 -> 90000000 | F8: =B8 -> 450 | G8: =C8 -> 500.2
A9: 80 | B9: 450 | C9: 487.4 | E9: =A9*1000000 -> 80000000 | F9: =B9 -> 450 | G9: =C9 -> 487.4
A10: 70 | B10: 450 | C10: 472.6 | E10: =A10*1000000 -> 70000000 | F10: =B10 -> 450 | G10: =C10 -> 472.6
A11: 60 | B11: 450 | C11: 455.2 | E11: =A11*1000000 -> 60000000 | F11: =B11 -> 450 | G11: =C11 -> 455.2
A12: 50 | B12: 450 | C12: 433.4 | E12: =A12*1000000 -> 50000000 | F12: =B12 -> 450 | G12: =C12 -> 433.4
A13: 40 | B13: 450 | C13: 403.7 | E13: =A13*1000000 -> 40000000 | F13: =B13 -> 450 | G13: =C13 -> 403.7
... A25: 50 | B25: 500 | C25: 350.9 | E25: =A25*1000000 -> 50000000 | F25: =B25 -> 500 | G25: =C25 -> 350.9

Sheet 0367 table 1
A1: P (atm) | B1: T © | C1: Z | E1: P (Pa) | F1: T (K) | G1: rho (kg/m3) | I1: R_NH3
A2: 506.2 | B2: 300 | C2: 0.7346 | E2: =A2*101325 -> 51290715 | F2: =B2+273.15 -> 573.15 | G2: =E2/($I$2*C2*F2) -> 249.52454 | I2: 488.20956
A3: 760.7 | B3: 300 | C3: 0.8214 | E3: =A3*101325 -> 77077928 | F3: =B3+273.15 -> 573.15 | G3: =E3/($I$2*C3*F3) -> 335.35189
A4: 1054.1 | B4: 300 | C4: 0.9623 | E4: =A4*101325 -> 1.0680668e+08 | F4: =B4+273.15 -> 573.15 | G4: =E4/($I$2*C4*F4) -> 396.6554
A5: 1502 | B5: 300 | C5: 1.1997 | E5: =A5*101325 -> 152190150 | F5: =B5+273.15 -> 573.15 | G5: =E5/($I$2*C5*F5) -> 453.35594
A6: 517.3 | B6: 350 | C6: 0.8239 | E6: =A6*101325 -> 52415422 | F6: =B6+273.15 -> 623.15 | G6: =E6/($I$2*C6*F6) -> 209.11525
A7: 775.1 | B7: 350 | C7: 0.8868 | E7: =A7*101325 -> 78537008 | F7: =B7+273.15 -> 623.15 | G7: =E7/($I$2*C7*F7) -> 291.10508
A8: 1013.5 | B8: 350 | C8: 0.978 | E8: =A8*101325 -> 1.0269289e+08 | F8: =B8+273.15 -> 623.15 | G8: =E8/($I$2*C8*F8) -> 345.14583
A9: 1497.7 | B9: 350 | C9: 1.2012 | E9: =A9*101325 -> 1.5175445e+08 | F9: =B9+273.15 -> 623.15 | G9: =E9/($I$2*C9*F9) -> 415.26683
A10: 1989.3 | B10: 350 | C10: 1.4399 | E10: =A10*101325 -> 2.0156582e+08 | F10: =B10+273.15 -> 623.15 | G10: =E10/($I$2*C10*F10) -> 460.13544
A11: 2215.1 | B11: 350 | C11: 1.5505 | E11: =A11*101325 -> 2.2444501e+08 | F11: =B11+273.15 -> 623.15 | G11: =E11/($I$2*C11*F11) -> 475.81629
A12: 2418.2 | B12: 350 | C12: 1.648 | E12: =A12*101325 -> 2.4502411e+08 | F12: =B12+273.15 -> 623.15 | G12: =E12/($I$2*C12*F12) -> 488.71171
A13: 513.9 | B13: 400 | C13: 0.8875 | E13: =A13*101325 -> 52070918 | F13: =B13+273.15 -> 673.15 | G13: =E13/($I$2*C13*F13) -> 178.52899
A14: 780.2 | B14: 400 | C14: 0.9463 | E14: =A14*101325 -> 79053765 | F14: =B14+273.15 -> 673.15 | G14: =E14/($I$2*C14*F14) -> 254.20003
... A28: 2280 | B28: 450 | C28: 1.5151 | E28: =A28*101325 -> 231021000 | F28: =B28+273.15 -> 723.15 | G28: =E28/($I$2*C28*F28) -> 431.89233

Sheet 0365 table 1
A1: P (atm) | B1: T © | C1: rho (cm3/g) | E1: P | F1: T | G1: rho
A2: 283.1 | B2: -20 | C2: 1.4754 | E2: =A2*101325 -> 28685108 | F2: =B2+273.15 -> 253.15 | G2: =1/C2*0.001*1000000 -> 677.7823
A3: 469.5 | B3: -20 | C3: 1.4538 | E3: =A3*101325 -> 47572088 | F3: =B3+273.15 -> 253.15 | G3: =1/C3*0.001*1000000 -> 687.85252
A4: 654.9 | B4: -20 | C4: 1.4371 | E4: =A4*101325 -> 66357742 | F4: =B4+273.15 -> 253.15 | G4: =1/C4*0.001*1000000 -> 695.8458
A5: 841.4 | B5: -20 | C5: 1.4207 | E5: =A5*101325 -> 85254855 | F5: =B5+273.15 -> 253.15 | G5: =1/C5*0.001*1000000 -> 703.87837
A6: 1027.9 | B6: -20 | C6: 1.4093 | E6: =A6*101325 -> 1.0415197e+08 | F6: =B6+273.15 -> 253.15 | G6: =1/C6*0.001*1000000 -> 709.57213
A7: 1214.1 | B7: -20 | C7: 1.3949 | E7: =A7*101325 -> 1.2301868e+08 | F7: =B7+273.15 -> 253.15 | G7: =1/C7*0.001*1000000 -> 716.89727
A8: 1400.5 | B8: -20 | C8: 1.3839 | E8: =A8*101325 -> 1.4190566e+08 | F8: =B8+273.15 -> 253.15 | G8: =1/C8*0.001*1000000 -> 722.59556
A9: 1587.2 | B9: -20 | C9: 1.3757 | E9: =A9*101325 -> 160823040 | F9: =B9+273.15 -> 253.15 | G9: =1/C9*0.001*1000000 -> 726.90267
A10: 283.1 | B10: 0 | C10: 1.5268 | E10: =A10*101325 -> 28685108 | F10: =B10+273.15 -> 273.15 | G10: =1/C10*0.001*1000000 -> 654.96463
A11: 469.5 | B11: 0 | C11: 1.5009 | E11: =A11*101325 -> 47572088 | F11: =B11+273.15 -> 273.15 | G11: =1/C11*0.001*1000000 -> 666.26691
A12: 654.9 | B12: 0 | C12: 1.4812 | E12: =A12*101325 -> 66357742 | F12: =B12+273.15 -> 273.15 | G12: =1/C12*0.001*1000000 -> 675.12827
A13: 841.4 | B13: 0 | C13: 1.4636 | E13: =A13*101325 -> 85254855 | F13: =B13+273.15 -> 273.15 | G13: =1/C13*0.001*1000000 -> 683.24679
... A38: 1742.1 | B38: 40 | C38: 1.4639 | E38: =A38*101325 -> 1.7651828e+08 | F38: =B38+273.15 -> 313.15 | G38: =1/C38*0.001*1000000 -> 683.10677

Sheet 0364 table 1
A1: P (MPa) | B1: T (K) | C1: rho (kg/m3) | E1: P (Pa) | F1: T (K) | G1: rho (kg/m3)
A2: 17 | B2: 310 | C2: 600.71 | E2: =A2*1000000 -> 17000000 | F2: =B2 -> 310 | G2: =C2 -> 600.71
A3: 16 | B3: 310 | C3: 599.8 | E3: =A3*1000000 -> 16000000 | F3: =B3 -> 310 | G3: =C3 -> 599.8
A4: 15 | B4: 310 | C4: 598.87 | E4: =A4*1000000 -> 15000000 | F4: =B4 -> 310 | G4: =C4 -> 598.87
A5: 14 | B5: 310 | C5: 597.84 | E5: =A5*1000000 -> 14000000 | F5: =B5 -> 310 | G5: =C5 -> 597.84
A6: 13 | B6: 310 | C6: 596.93 | E6: =A6*1000000 -> 13000000 | F6: =B6 -> 310 | G6: =C6 -> 596.93
A7: 12 | B7: 310 | C7: 595.93 | E7: =A7*1000000 -> 12000000 | F7: =B7 -> 310 | G7: =C7 -> 595.93
A8: 11 | B8: 310 | C8: 594.91 | E8: =A8*1000000 -> 11000000 | F8: =B8 -> 310 | G8: =C8 -> 594.91
A9: 10 | B9: 310 | C9: 594.01 | E9: =A9*1000000 -> 10000000 | F9: =B9 -> 310 | G9: =C9 -> 594.01
A10: 9 | B10: 310 | C10: 592.98 | E10: =A10*1000000 -> 9000000 | F10: =B10 -> 310 | G10: =C10 -> 592.98
A11: 8 | B11: 310 | C11: 591.99 | E11: =A11*1000000 -> 8000000 | F11: =B11 -> 310 | G11: =C11 -> 591.99
A12: 7 | B12: 310 | C12: 590.82 | E12: =A12*1000000 -> 7000000 | F12: =B12 -> 310 | G12: =C12 -> 590.82
A13: 6 | B13: 310 | C13: 589.75 | E13: =A13*1000000 -> 6000000 | F13: =B13 -> 310 | G13: =C13 -> 589.75
... A128: 10.35 | B128: 400 | C128: 345.58 | E128: =A128*1000000 -> 10350000 | F128: =B128 -> 400 | G128: =C128 -> 345.58

Sheet 0363 table 2
A1: P (atm) | B1: T (deg) | C1: P*v (atm*cc/g) | E1: P | F1: T | G1: rho
A2: 100 | B2: 10 | C2: 158.5 | E2: =A2*101325 -> 10132500 | F2: =B2+273.15 -> 283.15 | G2: =1/C2*0.001*1000000*A2 -> 630.91483
A3: 100 | B3: 20 | C3: 162 | E3: =A3*101325 -> 10132500 | F3: =B3+273.15 -> 293.15 | G3: =1/C3*0.001*1000000*A3 -> 617.28395
A4: 100 | B4: 30 | C4: 165.8 | E4: =A4*101325 -> 10132500 | F4: =B4+273.15 -> 303.15 | G4: =1/C4*0.001*1000000*A4 -> 603.13631
A5: 100 | B5: 40 | C5: 169.2 | E5: =A5*101325 -> 10132500 | F5: =B5+273.15 -> 313.15 | G5: =1/C5*0.001*1000000*A5 -> 591.01655
A6: 100 | B6: 50 | C6: 173 | E6: =A6*101325 -> 10132500 | F6: =B6+273.15 -> 323.15 | G6: =1/C6*0.001*1000000*A6 -> 578.03468
A7: 100 | B7: 60 | C7: 178 | E7: =A7*101325 -> 10132500 | F7: =B7+273.15 -> 333.15 | G7: =1/C7*0.001*1000000*A7 -> 561.79775
A8: 100 | B8: 70 | C8: 183.7 | E8: =A8*101325 -> 10132500 | F8: =B8+273.15 -> 343.15 | G8: =1/C8*0.001*1000000*A8 -> 544.36581
A9: 100 | B9: 80 | C9: 190 | E9: =A9*101325 -> 10132500 | F9: =B9+273.15 -> 353.15 | G9: =1/C9*0.001*1000000*A9 -> 526.31579
A10: 100 | B10: 90 | C10: 199 | E10: =A10*101325 -> 10132500 | F10: =B10+273.15 -> 363.15 | G10: =1/C10*0.001*1000000*A10 -> 502.51256
A11: 100 | B11: 100 | C11: 208.2 | E11: =A11*101325 -> 10132500 | F11: =B11+273.15 -> 373.15 | G11: =1/C11*0.001*1000000*A11 -> 480.3074
A12: 100 | B12: 110 | C12: 223.5 | E12: =A12*101325 -> 10132500 | F12: =B12+273.15 -> 383.15 | G12: =1/C12*0.001*1000000*A12 -> 447.42729
A13: 200 | B13: 10 | C13: 318.5 | E13: =A13*101325 -> 20265000 | F13: =B13+273.15 -> 283.15 | G13: =1/C13*0.001*1000000*A13 -> 627.94349
... A215: 1100 | B215: 210 | C215: 2225 | E215: =A215*101325 -> 111457500 | F215: =B215+273.15 -> 483.15 | G215: =1/C215*0.001*1000000*A215 -> 494.38202

Sheet 0363 table1
A1: PV (atm*cc/g) | B1: T © | C1: rho (cc/g) | E1: P | F1: T | G1: rho
A2: 1548 | B2: 29.84 | C2: 1.5 | E2: =A2/C2*101325 -> 104567400 | F2: =B2+273.15 -> 302.99 | G2: =1/C2*0.001*1000000 -> 666.66667
A3: 1703.5 | B3: 34.86 | C3: 1.5 | E3: =A3/C3*101325 -> 1.1507143e+08 | F3: =B3+273.15 -> 308.01 | G3: =1/C3*0.001*1000000 -> 666.66667
A4: 1013.2 | B4: 29.84 | C4: 1.55 | E4: =A4/C4*101325 -> 66233865 | F4: =B4+273.15 -> 302.99 | G4: =1/C4*0.001*1000000 -> 645.16129
A5: 1161 | B5: 34.86 | C5: 1.55 | E5: =A5/C5*101325 -> 75895694 | F5: =B5+273.15 -> 308.01 | G5: =1/C5*0.001*1000000 -> 645.16129
A6: 1327 | B6: 44.81 | C6: 1.55 | E6: =A6/C6*101325 -> 86747274 | F6: =B6+273.15 -> 317.96 | G6: =1/C6*0.001*1000000 -> 645.16129
A7: 1576 | B7: 49.83 | C7: 1.55 | E7: =A7/C7*101325 -> 1.0302465e+08 | F7: =B7+273.15 -> 322.98 | G7: =1/C7*0.001*1000000 -> 645.16129
A8: 1604 | B8: 54.88 | C8: 1.55 | E8: =A8/C8*101325 -> 1.0485503e+08 | F8: =B8+273.15 -> 328.03 | G8: =1/C8*0.001*1000000 -> 645.16129
A9: 547.2 | B9: 29.84 | C9: 1.6 | E9: =A9/C9*101325 -> 34653150 | F9: =B9+273.15 -> 302.99 | G9: =1/C9*0.001*1000000 -> 625
A10: 681.5 | B10: 34.86 | C10: 1.6 | E10: =A10/C10*101325 -> 43158117 | F10: =B10+273.15 -> 308.01 | G10: =1/C10*0.001*1000000 -> 625
A11: 885 | B11: 44.81 | C11: 1.6 | E11: =A11/C11*101325 -> 56045391 | F11: =B11+273.15 -> 317.96 | G11: =1/C11*0.001*1000000 -> 625
A12: 1106 | B12: 49.83 | C12: 1.6 | E12: =A12/C12*101325 -> 70040906 | F12: =B12+273.15 -> 322.98 | G12: =1/C12*0.001*1000000 -> 625
A13: 1150 | B13: 54.88 | C13: 1.6 | E13: =A13/C13*101325 -> 72827344 | F13: =B13+273.15 -> 328.03 | G13: =1/C13*0.001*1000000 -> 625
... A148: 1254 | B148: 200.701 | C148: 6 | E148: =A148/C148*101325 -> 21176925 | F148: =B148+273.15 -> 473.851 | G148: =1/C148*0.001*1000000 -> 166.66667

Sheet 0362 table 2
A1: P (Mpa) | B1: T (K) | C1: rho (kg/m3) | E1: P | F1: T | G1: rho
A2: 17 | B2: 310 | C2: 601.08 | E2: =A2*1000000 -> 17000000 | F2: =B2 -> 310 | G2: =C2 -> 601.08
A3: 16 | B3: 310 | C3: 600.17 | E3: =A3*1000000 -> 16000000 | F3: =B3 -> 310 | G3: =C3 -> 600.17
A4: 15 | B4: 310 | C4: 599.22 | E4: =A4*1000000 -> 15000000 | F4: =B4 -> 310 | G4: =C4 -> 599.22
A5: 14 | B5: 310 | C5: 598.28 | E5: =A5*1000000 -> 14000000 | F5: =B5 -> 310 | G5: =C5 -> 598.28
A6: 13 | B6: 310 | C6: 597.3 | E6: =A6*1000000 -> 13000000 | F6: =B6 -> 310 | G6: =C6 -> 597.3
A7: 12 | B7: 310 | C7: 596.33 | E7: =A7*1000000 -> 12000000 | F7: =B7 -> 310 | G7: =C7 -> 596.33
A8: 11 | B8: 310 | C8: 595.34 | E8: =A8*1000000 -> 11000000 | F8: =B8 -> 310 | G8: =C8 -> 595.34
A9: 10 | B9: 310 | C9: 594.3 | E9: =A9*1000000 -> 10000000 | F9: =B9 -> 310 | G9: =C9 -> 594.3
A10: 9 | B10: 310 | C10: 593.37 | E10: =A10*1000000 -> 9000000 | F10: =B10 -> 310 | G10: =C10 -> 593.37
A11: 8 | B11: 310 | C11: 592.39 | E11: =A11*1000000 -> 8000000 | F11: =B11 -> 310 | G11: =C11 -> 592.39
A12: 7 | B12: 310 | C12: 591.32 | E12: =A12*1000000 -> 7000000 | F12: =B12 -> 310 | G12: =C12 -> 591.32
A13: 6 | B13: 310 | C13: 590.19 | E13: =A13*1000000 -> 6000000 | F13: =B13 -> 310 | G13: =C13 -> 590.19
... A203: 10.35 | B203: 400 | C203: 345.56 | E203: =A203*1000000 -> 10350000 | F203: =B203 -> 400 | G203: =C203 -> 345.56

Sheet 0361 table 2
A1: P (Mpa) | B1: T(K) | C1: rho(kg/m3) | E1: P | F1: T | G1: rho
A2: 200 | B2: 310 | C2: 693.15 | E2: =A2*1000000 -> 200000000 | F2: =B2 -> 310 | G2: =C2 -> 693.15
A3: 190 | B3: 310 | C3: 689.73 | E3: =A3*1000000 -> 190000000 | F3: =B3 -> 310 | G3: =C3 -> 689.73
A4: 180 | B4: 310 | C4: 686.37 | E4: =A4*1000000 -> 180000000 | F4: =B4 -> 310 | G4: =C4 -> 686.37
A5: 170 | B5: 310 | C5: 682.74 | E5: =A5*1000000 -> 170000000 | F5: =B5 -> 310 | G5: =C5 -> 682.74
A6: 160 | B6: 310 | C6: 678.88 | E6: =A6*1000000 -> 160000000 | F6: =B6 -> 310 | G6: =C6 -> 678.88
A7: 150 | B7: 310 | C7: 675.04 | E7: =A7*1000000 -> 150000000 | F7: =B7 -> 310 | G7: =C7 -> 675.04
A8: 140 | B8: 310 | C8: 671.05 | E8: =A8*1000000 -> 140000000 | F8: =B8 -> 310 | G8: =C8 -> 671.05
A9: 130 | B9: 310 | C9: 666.73 | E9: =A9*1000000 -> 130000000 | F9: =B9 -> 310 | G9: =C9 -> 666.73
A10: 120 | B10: 310 | C10: 662.38 | E10: =A10*1000000 -> 120000000 | F10: =B10 -> 310 | G10: =C10 -> 662.38
A11: 110 | B11: 310 | C11: 657.9 | E11: =A11*1000000 -> 110000000 | F11: =B11 -> 310 | G11: =C11 -> 657.9
A12: 100 | B12: 310 | C12: 653.02 | E12: =A12*1000000 -> 100000000 | F12: =B12 -> 310 | G12: =C12 -> 653.02
A13: 90 | B13: 310 | C13: 648.12 | E13: =A13*1000000 -> 90000000 | F13: =B13 -> 310 | G13: =C13 -> 648.12
... A163: 5 | B163: 360 | C163: 492.03 | E163: =A163*1000000 -> 5000000 | F163: =B163 -> 360 | G163: =C163 -> 492.03

Sheet 0360 table 4
A1: P (Mpa) | B1: T (K) | C1: rho (g/cm3) | E1: P | F1: T | G1: rho
A2: 0.558 | B2: 279.37 | C2: 0.6296 | E2: =A2*1000000 -> 558000 | F2: =B2 -> 279.37 | G2: =C2*0.001*1000000 -> 629.6
A3: 0.558 | B3: 279.68 | C3: 0.6292 | E3: =A3*1000000 -> 558000 | F3: =B3 -> 279.68 | G3: =C3*0.001*1000000 -> 629.2
A4: 0.577 | B4: 280.6 | C4: 0.6281 | E4: =A4*1000000 -> 577000 | F4: =B4 -> 280.6 | G4: =C4*0.001*1000000 -> 628.1
A5: 0.613 | B5: 282.53 | C5: 0.6251 | E5: =A5*1000000 -> 613000 | F5: =B5 -> 282.53 | G5: =C5*0.001*1000000 -> 625.1
A6: 1.021 | B6: 297.39 | C6: 0.604 | E6: =A6*1000000 -> 1021000 | F6: =B6 -> 297.39 | G6: =C6*0.001*1000000 -> 604
A7: 1.055 | B7: 299.07 | C7: 0.6017 | E7: =A7*1000000 -> 1055000 | F7: =B7 -> 299.07 | G7: =C7*0.001*1000000 -> 601.7
A8: 1.071 | B8: 299.4 | C8: 0.6014 | E8: =A8*1000000 -> 1071000 | F8: =B8 -> 299.4 | G8: =C8*0.001*1000000 -> 601.4
A9: 1.115 | B9: 300.74 | C9: 0.5991 | E9: =A9*1000000 -> 1115000 | F9: =B9 -> 300.74 | G9: =C9*0.001*1000000 -> 599.1
A10: 1.764 | B10: 316.94 | C10: 0.5741 | E10: =A10*1000000 -> 1764000 | F10: =B10 -> 316.94 | G10: =C10*0.001*1000000 -> 574.1
A11: 1.855 | B11: 319.48 | C11: 0.5695 | E11: =A11*1000000 -> 1855000 | F11: =B11 -> 319.48 | G11: =C11*0.001*1000000 -> 569.5
A12: 1.866 | B12: 319.85 | C12: 0.5677 | E12: =A12*1000000 -> 1866000 | F12: =B12 -> 319.85 | G12: =C12*0.001*1000000 -> 567.7
A13: 1.9 | B13: 319.9 | C13: 0.5689 | E13: =A13*1000000 -> 1900000 | F13: =B13 -> 319.9 | G13: =C13*0.001*1000000 -> 568.9
... A29: 8.542 | B29: 388.16 | C29: 0.4137 | E29: =A29*1000000 -> 8542000 | F29: =B29 -> 388.16 | G29: =C29*0.001*1000000 -> 413.7

Sheet 0360 table 3
A1: P (Mpa) | B1: T (K) | C1: rho (g/cm3) | E1: P | F1: T | G1: rho
A2: 0.558 | B2: 280.29 | C2: 0.0035 | E2: =A2*1000000 -> 558000 | F2: =B2 -> 280.29 | G2: =C2*0.001*1000000 -> 3.5
A3: 0.577 | B3: 282.6 | C3: 0.0035 | E3: =A3*1000000 -> 577000 | F3: =B3 -> 282.6 | G3: =C3*0.001*1000000 -> 3.5
A4: 1.021 | B4: 299.84 | C4: 0.0072 | E4: =A4*1000000 -> 1021000 | F4: =B4 -> 299.84 | G4: =C4*0.001*1000000 -> 7.2
A5: 1.9 | B5: 322.36 | C5: 0.0136 | E5: =A5*1000000 -> 1900000 | F5: =B5 -> 322.36 | G5: =C5*0.001*1000000 -> 13.6
A6: 2.915 | B6: 339.42 | C6: 0.0217 | E6: =A6*1000000 -> 2915000 | F6: =B6 -> 339.42 | G6: =C6*0.001*1000000 -> 21.7
A7: 4.583 | B7: 359.48 | C7: 0.0364 | E7: =A7*1000000 -> 4583000 | F7: =B7 -> 359.48 | G7: =C7*0.001*1000000 -> 36.4
A8: 6.876 | B8: 379.12 | C8: 0.0616 | E8: =A8*1000000 -> 6876000 | F8: =B8 -> 379.12 | G8: =C8*0.001*1000000 -> 61.6
A9: 8.597 | B9: 390.95 | C9: 0.0867 | E9: =A9*1000000 -> 8597000 | F9: =B9 -> 390.95 | G9: =C9*0.001*1000000 -> 86.7

Sheet 359 table 1
A1: P (atm) | B1: T © | C1: rho (mol/L) | E1: P (Pa) | F1: T (K) | G1: rho (kg/m3) | I1: M_NH3
A2: 108.33 | B2: 131.05 | C2: 9.11 | E2: =A2*101325 -> 10976537 | F2: =B2+273.15 -> 404.2 | G2: =C2*$I$2*1000 -> 155.14804 | I2: =0.01703052 -> 0.01703052
A3: 108.55 | B3: 131.05 | C3: 9.396 | E3: =A3*101325 -> 10998829 | F3: =B3+273.15 -> 404.2 | G3: =C3*$I$2*1000 -> 160.01877
A4: 108.75 | B4: 131.05 | C4: 9.709 | E4: =A4*101325 -> 11019094 | F4: =B4+273.15 -> 404.2 | G4: =C4*$I$2*1000 -> 165.34932
A5: 108.89 | B5: 131.05 | C5: 10.042 | E5: =A5*101325 -> 11033279 | F5: =B5+273.15 -> 404.2 | G5: =C5*$I$2*1000 -> 171.02048
A6: 109.03 | B6: 131.05 | C6: 10.399 | E6: =A6*101325 -> 11047465 | F6: =B6+273.15 -> 404.2 | G6: =C6*$I$2*1000 -> 177.10038
A7: 109.14 | B7: 131.05 | C7: 11.784 | E7: =A7*101325 -> 11058610 | F7: =B7+273.15 -> 404.2 | G7: =C7*$I$2*1000 -> 200.68765
A8: 109.17 | B8: 131.05 | C8: 13.114 | E8: =A8*101325 -> 11061650 | F8: =B8+273.15 -> 404.2 | G8: =C8*$I$2*1000 -> 223.33824
A9: 109.17 | B9: 131.05 | C9: 13.114 | E9: =A9*101325 -> 11061650 | F9: =B9+273.15 -> 404.2 | G9: =C9*$I$2*1000 -> 223.33824
A10: 109.17 | B10: 131.05 | C10: 14.768 | E10: =A10*101325 -> 11061650 | F10: =B10+273.15 -> 404.2 | G10: =C10*$I$2*1000 -> 251.50672
A11: 109.31 | B11: 131.05 | C11: 17.42 | E11: =A11*101325 -> 11075836 | F11: =B11+273.15 -> 404.2 | G11: =C11*$I$2*1000 -> 296.67166
A12: 109.65 | B12: 131.05 | C12: 17.843 | E12: =A12*101325 -> 11110286 | F12: =B12+273.15 -> 404.2 | G12: =C12*$I$2*1000 -> 303.87557
A13: 110.32 | B13: 131.05 | C13: 18.297 | E13: =A13*101325 -> 11178174 | F13: =B13+273.15 -> 404.2 | G13: =C13*$I$2*1000 -> 311.60742
A14: 111.21 | B14: 131.05 | C14: 18.72 | E14: =A14*101325 -> 11268353 | F14: =B14+273.15 -> 404.2 | G14: =C14*$I$2*1000 -> 318.81133
... A101: 117.05 | B101: 133.96 | C101: 17.419 | E101: =A101*101325 -> 11860091 | F101: =B101+273.15 -> 407.11 | G101: =C101*$I$2*1000 -> 296.65463

Sheet 0358 table 5
A1: P (atm) | B1: T © | C1: Z | E1: P (Pa) | F1: T (K) | G1: rho(kg/m3) | I1: R_NH3 | J1: (from EOS.py)
A2: 50 | B2: 25 | C2: 0.05755 | E2: =A2*101325 -> 5066250 | F2: =B2+273.15 -> 298.15 | G2: =E2/(C2*$I$2*F2) -> 604.78387 | I2: 488.20956
A3: 75 | B3: 25 | C3: 0.086 | E3: =A3*101325 -> 7599375 | F3: =B3+273.15 -> 298.15 | G3: =E3/(C3*$I$2*F3) -> 607.06939
A4: 100 | B4: 25 | C4: 0.1143 | E4: =A4*101325 -> 10132500 | F4: =B4+273.15 -> 298.15 | G4: =E4/(C4*$I$2*F4) -> 609.01683
A5: 150 | B5: 25 | C5: 0.1702 | E5: =A5*101325 -> 15198750 | F5: =B5+273.15 -> 298.15 | G5: =E5/(C5*$I$2*F5) -> 613.48963
A6: 200 | B6: 25 | C6: 0.22544 | E6: =A6*101325 -> 20265000 | F6: =B6+273.15 -> 298.15 | G6: =E6/(C6*$I$2*F6) -> 617.55344
A7: 250 | B7: 25 | C7: 0.28 | E7: =A7*101325 -> 25331250 | F7: =B7+273.15 -> 298.15 | G7: =E7/(C7*$I$2*F7) -> 621.52342
A8: 300 | B8: 25 | C8: 0.3339 | E8: =A8*101325 -> 30397500 | F8: =B8+273.15 -> 298.15 | G8: =E8/(C8*$I$2*F8) -> 625.43237
A9: 400 | B9: 25 | C9: 0.4398 | E9: =A9*101325 -> 40530000 | F9: =B9+273.15 -> 298.15 | G9: =E9/(C9*$I$2*F9) -> 633.11163
A10: 500 | B10: 25 | C10: 0.5436 | E10: =A10*101325 -> 50662500 | F10: =B10+273.15 -> 298.15 | G10: =E10/(C10*$I$2*F10) -> 640.27431
A11: 50 | B11: 50 | C11: 0.05672 | E11: =A11*101325 -> 5066250 | F11: =B11+273.15 -> 323.15 | G11: =E11/(C11*$I$2*F11) -> 566.16101
A12: 75 | B12: 50 | C12: 0.08459 | E12: =A12*101325 -> 7599375 | F12: =B12+273.15 -> 323.15 | G12: =E12/(C12*$I$2*F12) -> 569.44058
A13: 100 | B13: 50 | C13: 0.1122 | E13: =A13*101325 -> 10132500 | F13: =B13+273.15 -> 323.15 | G13: =E13/(C13*$I$2*F13) -> 572.41805
A14: 150 | B14: 50 | C14: 0.1665 | E14: =A14*101325 -> 15198750 | F14: =B14+273.15 -> 323.15 | G14: =E14/(C14*$I$2*F14) -> 578.60635
... A43: 500 | B43: 125 | C43: 0.5088 | E43: =A43*101325 -> 50662500 | F43: =B43+273.15 -> 398.15 | G43: =E43/(C43*$I$2*F43) -> 512.25537

Sheet 0358 table 2
A1: 1/V (mol/L) | B1: T(C) | C1: Z | E1: P (Pa) | F1: T (K) | G1: rho(kg/m3) | I1: M_NH3 | J1: R_NH3 | K1: (from EOS.py)
A2: 0.2 | B2: 25 | C2: 0.9477 | E2: =C2*G2*$J$2*F2 -> 469861.52 | F2: =B2+273.15 -> 298.15 | G2: =A2*$I$2*1000 -> 3.406104 | I2: 0.01703052 | J2: 488.20956
A3: 0.4 | B3: 25 | C3: 0.8926 | E3: =C3*G3*$J$2*F3 -> 885086.82 | F3: =B3+273.15 -> 298.15 | G3: =A3*$I$2*1000 -> 6.812208
A4: 0.45 | B4: 25 | C4: 0.8715 | E4: =C4*G4*$J$2*F4 -> 972184.97 | F4: =B4+273.15 -> 298.15 | G4: =A4*$I$2*1000 -> 7.663734
A5: 0.5 | B5: 25 | C5: 0.813 | E5: =C5*G5*$J$2*F5 -> 1007696 | F5: =B5+273.15 -> 298.15 | G5: =A5*$I$2*1000 -> 8.51526
A6: 0.2 | B6: 50 | C6: 0.9595 | E6: =C6*G6*$J$2*F6 -> 515600.49 | F6: =B6+273.15 -> 323.15 | G6: =A6*$I$2*1000 -> 3.406104
A7: 0.4 | B7: 50 | C7: 0.9195 | E7: =C7*G7*$J$2*F7 -> 988211.88 | F7: =B7+273.15 -> 323.15 | G7: =A7*$I$2*1000 -> 6.812208
A8: 0.5 | B8: 50 | C8: 0.8992 | E8: =C8*G8*$J$2*F8 -> 1207993.6 | F8: =B8+273.15 -> 323.15 | G8: =A8*$I$2*1000 -> 8.51526
A9: 0.6 | B9: 50 | C9: 0.8798 | E9: =C9*G9*$J$2*F9 -> 1418317.8 | F9: =B9+273.15 -> 323.15 | G9: =A9*$I$2*1000 -> 10.218312
A10: 0.7 | B10: 50 | C10: 0.8603 | E10: =C10*G10*$J$2*F10 -> 1618029 | F10: =B10+273.15 -> 323.15 | G10: =A10*$I$2*1000 -> 11.921364
A11: 0.8 | B11: 50 | C11: 0.8393 | E11: =C11*G11*$J$2*F11 -> 1804037.5 | F11: =B11+273.15 -> 323.15 | G11: =A11*$I$2*1000 -> 13.624416
A12: 0.85 | B12: 50 | C12: 0.8275 | E12: =C12*G12*$J$2*F12 -> 1889841 | F12: =B12+273.15 -> 323.15 | G12: =A12*$I$2*1000 -> 14.475942
A13: 0.9 | B13: 50 | C13: 0.814 | E13: =C13*G13*$J$2*F13 -> 1968363.3 | F13: =B13+273.15 -> 323.15 | G13: =A13*$I$2*1000 -> 15.327468
A14: 0.95 | B14: 50 | C14: 0.7946 | E14: =C14*G14*$J$2*F14 -> 2028198.8 | F14: =B14+273.15 -> 323.15 | G14: =A14*$I$2*1000 -> 16.178994
... A52: 6 | B52: 125 | C52: 0.4812 | E52: =C52*G52*$J$2*F52 -> 9557796.4 | F52: =B52+273.15 -> 398.15 | G52: =A52*$I$2*1000 -> 102.18312

Sheet 0358 table 1
A1: P (atm) | B1: T(C) | C1: Z | E1: P (Pa) | F1: T (K) | G1: rho(kg/m3) | I1: R_NH3 | J1: (from EOS.py)
A2: 2 | B2: 25 | C2: 0.978 | E2: =A2*101325 -> 202650 | F2: =B2+273.15 -> 298.15 | G2: =E2/(C2*$I$2*F2) -> 1.4235301 | I2: 488.20956
A3: 4 | B3: 25 | C3: 0.9546 | E3: =A3*101325 -> 405300 | F3: =B3+273.15 -> 298.15 | G3: =E3/(C3*$I$2*F3) -> 2.9168499
A4: 6 | B4: 25 | C4: 0.9308 | E4: =A4*101325 -> 607950 | F4: =B4+273.15 -> 298.15 | G4: =E4/(C4*$I$2*F4) -> 4.487148
A5: 7 | B5: 25 | C5: 0.9171 | E5: =A5*101325 -> 709275 | F5: =B5+273.15 -> 298.15 | G5: =E5/(C5*$I$2*F5) -> 5.3132086
A6: 8 | B6: 25 | C6: 0.9027 | E6: =A6*101325 -> 810600 | F6: =B6+273.15 -> 298.15 | G6: =E6/(C6*$I$2*F6) -> 6.1691036
A7: 9 | B7: 25 | C7: 0.8862 | E7: =A7*101325 -> 911925 | F7: =B7+273.15 -> 298.15 | G7: =E7/(C7*$I$2*F7) -> 7.0694607
A8: 9.3 | B8: 25 | C8: 0.88 | E8: =A8*101325 -> 942322.5 | F8: =B8+273.15 -> 298.15 | G8: =E8/(C8*$I$2*F8) -> 7.3565772
A9: 9.5 | B9: 25 | C9: 0.8743 | E9: =A9*101325 -> 962587.5 | F9: =B9+273.15 -> 298.15 | G9: =E9/(C9*$I$2*F9) -> 7.5637758
A10: 9.7 | B10: 25 | C10: 0.8656 | E10: =A10*101325 -> 982852.5 | F10: =B10+273.15 -> 298.15 | G10: =E10/(C10*$I$2*F10) -> 7.8006359
A11: 2 | B11: 50 | C11: 0.9856 | E11: =A11*101325 -> 202650 | F11: =B11+273.15 -> 323.15 | G11: =E11/(C11*$I$2*F11) -> 1.3032732
A12: 4 | B12: 50 | C12: 0.9704 | E12: =A12*101325 -> 405300 | F12: =B12+273.15 -> 323.15 | G12: =E12/(C12*$I$2*F12) -> 2.6473745
A13: 6 | B13: 50 | C13: 0.9544 | E13: =A13*101325 -> 607950 | F13: =B13+273.15 -> 323.15 | G13: =E13/(C13*$I$2*F13) -> 4.0376344
A14: 8 | B14: 50 | C14: 0.9372 | E14: =A14*101325 -> 810600 | F14: =B14+273.15 -> 323.15 | G14: =E14/(C14*$I$2*F14) -> 5.4823137
... A60: 95 | B60: 125 | C60: 0.472 | E60: =A60*101325 -> 9625875 | F60: =B60+273.15 -> 398.15 | G60: =E60/(C60*$I$2*F60) -> 104.91685

Sheet 0357 table 2
A1: P (atm) | B1: T (C) | C1: rho (cc/g) | E1: P (Pa) | F1: T (K) | G1: rho (kg/m3)
A2: 29.59 | B2: 325 | C2: 95 | E2: =A2*101325 -> 2998206.8 | F2: =B2+273.15 -> 598.15 | G2: =1/C2*0.001*1000000 -> 10.526316
A3: 31.22 | B3: 325 | C3: 90 | E3: =A3*101325 -> 3163366.5 | F3: =B3+273.15 -> 598.15 | G3: =1/C3*0.001*1000000 -> 11.111111
A4: 35.04 | B4: 325 | C4: 80 | E4: =A4*101325 -> 3550428 | F4: =B4+273.15 -> 598.15 | G4: =1/C4*0.001*1000000 -> 12.5
A5: 39.9 | B5: 325 | C5: 70 | E5: =A5*101325 -> 4042867.5 | F5: =B5+273.15 -> 598.15 | G5: =1/C5*0.001*1000000 -> 14.285714
A6: 46.34 | B6: 325 | C6: 60 | E6: =A6*101325 -> 4695400.5 | F6: =B6+273.15 -> 598.15 | G6: =1/C6*0.001*1000000 -> 16.666667
A7: 55.24 | B7: 325 | C7: 50 | E7: =A7*101325 -> 5597193 | F7: =B7+273.15 -> 598.15 | G7: =1/C7*0.001*1000000 -> 20
A8: 61.11 | B8: 325 | C8: 45 | E8: =A8*101325 -> 6191970.8 | F8: =B8+273.15 -> 598.15 | G8: =1/C8*0.001*1000000 -> 22.222222
A9: 68.36 | B9: 325 | C9: 40 | E9: =A9*101325 -> 6926577 | F9: =B9+273.15 -> 598.15 | G9: =1/C9*0.001*1000000 -> 25
A10: 77.59 | B10: 325 | C10: 35 | E10: =A10*101325 -> 7861806.8 | F10: =B10+273.15 -> 598.15 | G10: =1/C10*0.001*1000000 -> 28.571429
A11: 89.69 | B11: 325 | C11: 30 | E11: =A11*101325 -> 9087839.2 | F11: =B11+273.15 -> 598.15 | G11: =1/C11*0.001*1000000 -> 33.333333
A12: 106.25 | B12: 325 | C12: 25 | E12: =A12*101325 -> 10765781 | F12: =B12+273.15 -> 598.15 | G12: =1/C12*0.001*1000000 -> 40
A13: 130.4 | B13: 325 | C13: 20 | E13: =A13*101325 -> 13212780 | F13: =B13+273.15 -> 598.15 | G13: =1/C13*0.001*1000000 -> 50
... A189: 0.865 | B189: -35 | C189: 1300 | E189: =A189*101325 -> 87646.125 | F189: =B189+273.15 -> 238.15 | G189: =1/C189*0.001*1000000 -> 0.76923077
