Workbook

Sheet all
A1: Paper | B1: P | C1: T | D1: y_H2 | E1: x_H2
A2: 307 | B2: ='0307-table1'!H2 -> 1538703.6 | C2: ='0307-table1'!I2 -> 277.59444 | D2: ='0307-table1'!J2 -> 0.6601
A3: 307 | B3: ='0307-table1'!H3 -> 2612700.4 | C3: ='0307-table1'!I3 -> 277.59444 | D3: ='0307-table1'!J3 -> 0.7907
A4: 307 | B4: ='0307-table1'!H4 -> 3441588.4 | C4: ='0307-table1'!I4 -> 277.59444 | D4: ='0307-table1'!J4 -> 0.837
A5: 307 | B5: ='0307-table1'!H5 -> 4825780.4 | C5: ='0307-table1'!I5 -> 277.59444 | D5: ='0307-table1'!J5 -> 0.8804
A6: 307 | B6: ='0307-table1'!H6 -> 7812176.8 | C6: ='0307-table1'!I6 -> 277.59444 | D6: ='0307-table1'!J6 -> 0.9218
A7: 307 | B7: ='0307-table1'!H7 -> 10376200 | C7: ='0307-table1'!I7 -> 277.59444 | D7: ='0307-table1'!J7 -> 0.9401
A8: 307 | B8: ='0307-table1'!H8 -> 14421287 | C8: ='0307-table1'!I8 -> 277.59444 | D8: ='0307-table1'!J8 -> 0.954
A9: 307 | B9: ='0307-table1'!H9 -> 22066197 | C9: ='0307-table1'!I9 -> 277.59444 | D9: ='0307-table1'!J9 -> 0.9638
A10: 307 | B10: ='0307-table1'!H10 -> 31719688 | C10: ='0307-table1'!I10 -> 277.59444 | D10: ='0307-table1'!J10 -> 0.9702
A11: 307 | B11: ='0307-table1'!H11 -> 35947900 | C11: ='0307-table1'!I11 -> 277.59444 | D11: ='0307-table1'!J11 -> 0.9707
A12: 307 | B12: ='0307-table1'!H12 -> 2455844.6 | C12: ='0307-table1'!I12 -> 310.92778 | D12: ='0307-table1'!J12 -> 0.3743
A13: 307 | B13: ='0307-table1'!H13 -> 3608855.3 | C13: ='0307-table1'!I13 -> 310.92778 | D13: ='0307-table1'!J13 -> 0.5551
... A50: 307 | B50: ='0307-table1'!H50 -> 31748370 | C50: ='0307-table1'!I50 -> 394.26111 | D50: ='0307-table1'!J50 -> 0.3534
A51: 307 | B51: ='0307-table2'!K2 -> 505385.91 | C51: ='0307-table2'!L2 -> 277.59444 | D51: ='0307-table2'!M2 -> 0 | E51: ='0307-table2'!N2 -> 0
A52: 307 | B52: ='0307-table2'!K3 -> 3447380 | C52: ='0307-table2'!L3 -> 277.59444 | D52: ='0307-table2'!M3 -> 0.837 | E52: ='0307-table2'!N3 -> 0.0021
A53: 307 | B53: ='0307-table2'!K4 -> 6894760 | C53: ='0307-table2'!L4 -> 277.59444 | D53: ='0307-table2'!M4 -> 0.9144 | E53: ='0307-table2'!N4 -> 0.004
A54: 307 | B54: ='0307-table2'!K5 -> 10342140 | C54: ='0307-table2'!L5 -> 277.59444 | D54: ='0307-table2'!M5 -> 0.9401 | E54: ='0307-table2'!N5 -> 0.0055
A55: 307 | B55: ='0307-table2'!K6 -> 13789520 | C55: ='0307-table2'!L6 -> 277.59444 | D55: ='0307-table2'!M6 -> 0.9524 | E55: ='0307-table2'!N6 -> 0.007
A56: 307 | B56: ='0307-table2'!K7 -> 17236900 | C56: ='0307-table2'!L7 -> 277.59444 | D56: ='0307-table2'!M7 -> 0.9595 | E56: ='0307-table2'!N7 -> 0.0085
A57: 307 | B57: ='0307-table2'!K8 -> 20684280 | C57: ='0307-table2'!L8 -> 277.59444 | D57: ='0307-table2'!M8 -> 0.964 | E57: ='0307-table2'!N8 -> 0.0102
A58: 307 | B58: ='0307-table2'!K9 -> 24131660 | C58: ='0307-table2'!L9 -> 277.59444 | D58: ='0307-table2'!M9 -> 0.9664 | E58: ='0307-table2'!N9 -> 0.012
A59: 307 | B59: ='0307-table2'!K10 -> 27579040 | C59: ='0307-table2'!L10 -> 277.59444 | D59: ='0307-table2'!M10 -> 0.969 | E59: ='0307-table2'!N10 -> 0.014
A60: 307 | B60: ='0307-table2'!K11 -> 31026420 | C60: ='0307-table2'!L11 -> 277.59444 | D60: ='0307-table2'!M11 -> 0.9705 | E60: ='0307-table2'!N11 -> 0.016
A61: 307 | B61: ='0307-table2'!K12 -> 34473800 | C61: ='0307-table2'!L12 -> 277.59444 | D61: ='0307-table2'!M12 -> 0.9715 | E61: ='0307-table2'!N12 -> 0.0181
A62: 307 | B62: ='0307-table2'!K13 -> 37921180 | C62: ='0307-table2'!L13 -> 277.59444 | D62: ='0307-table2'!M13 -> 0.9718 | E62: ='0307-table2'!N13 -> 0.0203
... A112: 307 | B112: ='0307-table2'!K63 -> 41368560 | C112: ='0307-table2'!L63 -> 394.26111 | D112: ='0307-table2'!M63 -> 0.3701 | E112: ='0307-table2'!N63 -> 0.15
A113: 501 | B113: ='0501-table2'!N2 -> 20215000 | C113: ='0501-table2'!O2 -> 298.15 | D113: ='0501-table2'!P2 -> 0.9304 | E113: ='0501-table2'!Q2 -> 0.014497203
A114: 501 | B114: ='0501-table2'!N3 -> 10070000 | C114: ='0501-table2'!O3 -> 298.15 | E114: ='0501-table2'!Q3 -> 0.007161985
A115: 501 | B115: ='0501-table2'!N4 -> 10020000 | C115: ='0501-table2'!O4 -> 298.15 | D115: ='0501-table2'!P4 -> 0.8751
A116: 501 | B116: ='0501-table2'!N5 -> 5345000 | C116: ='0501-table2'!O5 -> 298.15 | E116: ='0501-table2'!Q5 -> 0.00344976
A117: 501 | B117: ='0501-table2'!N6 -> 2890000 | C117: ='0501-table2'!O6 -> 298.15 | D117: ='0501-table2'!P6 -> 0.6145 | E117: ='0501-table2'!Q6 -> 0.0015549902
A118: 501 | B118: ='0501-table3'!E2 -> 2006000 | C118: ='0501-table3'!F2 -> 298.15 | D118: ='0501-table3'!G2 -> 0.4835
A119: 502 | B119: ='0502-table1'!K2 -> 5066250 | C119: ='0502-table1'!L2 -> 298.15 | E119: ='0502-table1'!M2 -> 0.0033834406
A120: 502 | B120: ='0502-table1'!K3 -> 10132500 | C120: ='0502-table1'!L3 -> 298.15 | E120: ='0502-table1'!M3 -> 0.0074424953
A121: 502 | B121: ='0502-table1'!K4 -> 20265000 | C121: ='0502-table1'!L4 -> 298.15 | E121: ='0502-table1'!M4 -> 0.015015984
A122: 502 | B122: ='0502-table1'!K5 -> 40530000 | C122: ='0502-table1'!L5 -> 298.15 | E122: ='0502-table1'!M5 -> 0.028141119
A123: 502 | B123: ='0502-table1'!K6 -> 60795000 | C123: ='0502-table1'!L6 -> 298.15 | E123: ='0502-table1'!M6 -> 0.039185776
A124: 502 | B124: ='0502-table1'!K7 -> 81060000 | C124: ='0502-table1'!L7 -> 298.15 | E124: ='0502-table1'!M7 -> 0.04884461
A125: 502 | B125: ='0502-table1'!K8 -> 101325000 | C125: ='0502-table1'!L8 -> 298.15 | E125: ='0502-table1'!M8 -> 0.056760602
...

Sheet sources
A1: Papers | B1: comments | C1: status
A2: 307 | B2: this is the data [0301] says it uses | C2: done
A3: 308 | B3: not a lot of data, only table 5 was used, table 5 is not fully experimental but is obtained from measurements | C3: done
A4: 314 | B4: not VLE, lkely single phase gaseous mixture, still useful but not VLE | C4: done
A5: 319 | B5: done | C5: done
A6: 500 | B6: relates to nitrogen-hydrogen-ammonia system, not relevant to me | C6: done
A7: 501 | B7: its in german | C7: done
A8: 502 | B8: done | C8: done
A9: 503 | B9: no actual experimental data, this relates to the developemnt of a method | C9: done
A10: 504 | B10: has very little data and detail | C10: done
A11: 505 | B11: its in russian, only table 1 provides raw experimental results, used Copilot to translate the table and document | C11: done
A12: 506 | B12: its in russian, used Copilot to translate the table and document | C12: done
A13: 511 | B13: not VLE, lkely single phase gaseous mixture, still useful but not VLE | C13: done

Sheet 0307-table1
A1: Pressure (PSI) | B1: Temperature (F) | C1: y_H2 | E1: Psi to Pa | F1: F to K | H1: P | I1: T | J1: y_H2 | K1: x_H2 | L1: K_H2 | M1: K_NH3
A2: 223.17 | B2: 40 | C2: 0.6601 | E2: 6894.76 | F2: (F-32)*5/9+273.15 | H2: =A2*$E$2 -> 1538703.6 | I2: =(B2-32)*5/9+273.15 -> 277.59444 | J2: =C2 -> 0.6601
A3: 378.94 | B3: 40 | C3: 0.7907 | H3: =A3*$E$2 -> 2612700.4 | I3: =(B3-32)*5/9+273.15 -> 277.59444 | J3: =C3 -> 0.7907
A4: 499.16 | B4: 40 | C4: 0.837 | H4: =A4*$E$2 -> 3441588.4 | I4: =(B4-32)*5/9+273.15 -> 277.59444 | J4: =C4 -> 0.837
A5: 699.92 | B5: 40 | C5: 0.8804 | H5: =A5*$E$2 -> 4825780.4 | I5: =(B5-32)*5/9+273.15 -> 277.59444 | J5: =C5 -> 0.8804
A6: 1133.06 | B6: 40 | C6: 0.9218 | H6: =A6*$E$2 -> 7812176.8 | I6: =(B6-32)*5/9+273.15 -> 277.59444 | J6: =C6 -> 0.9218
A7: 1504.94 | B7: 40 | C7: 0.9401 | H7: =A7*$E$2 -> 10376200 | I7: =(B7-32)*5/9+273.15 -> 277.59444 | J7: =C7 -> 0.9401
A8: 2091.63 | B8: 40 | C8: 0.954 | H8: =A8*$E$2 -> 14421287 | I8: =(B8-32)*5/9+273.15 -> 277.59444 | J8: =C8 -> 0.954
A9: 3200.43 | B9: 40 | C9: 0.9638 | H9: =A9*$E$2 -> 22066197 | I9: =(B9-32)*5/9+273.15 -> 277.59444 | J9: =C9 -> 0.9638
A10: 4600.55 | B10: 40 | C10: 0.9702 | H10: =A10*$E$2 -> 31719688 | I10: =(B10-32)*5/9+273.15 -> 277.59444 | J10: =C10 -> 0.9702
A11: 5213.8 | B11: 40 | C11: 0.9707 | H11: =A11*$E$2 -> 35947900 | I11: =(B11-32)*5/9+273.15 -> 277.59444 | J11: =C11 -> 0.9707
A12: 356.19 | B12: 100 | C12: 0.3743 | H12: =A12*$E$2 -> 2455844.6 | I12: =(B12-32)*5/9+273.15 -> 310.92778 | J12: =C12 -> 0.3743
A13: 523.42 | B13: 100 | C13: 0.5551 | H13: =A13*$E$2 -> 3608855.3 | I13: =(B13-32)*5/9+273.15 -> 310.92778 | J13: =C13 -> 0.5551
A14: 760.64 | B14: 100 | C14: 0.6732 | H14: =A14*$E$2 -> 5244430.2 | I14: =(B14-32)*5/9+273.15 -> 310.92778 | J14: =C14 -> 0.6732
... A50: 4604.71 | B50: 250 | C50: 0.3534 | H50: =A50*$E$2 -> 31748370 | I50: =(B50-32)*5/9+273.15 -> 394.26111 | J50: =C50 -> 0.3534

Sheet 0307-table2
A1: pressure (PSI) | B1: Temperature(F) | C1: y_H2 | D1: x_H2 | E1: K_H2 | F1: K_NH3 | H1: Psi to Pa | I1: F to K | K1: P | L1: T | M1: y_H2 | N1: x_H2 | O1: K_H2 | P1: K_NH3
A2: 73.3 | B2: 40 | C2: 0 | D2: 0 | F2: 1 | H2: 6894.76 | I2: (F-32)*5/9+273.15 | K2: =A2*$H$2 -> 505385.91 | L2: =(B2-32)*5/9+273.15 -> 277.59444 | M2: =C2 -> 0 | N2: =D2 -> 0 | P2: =F2 -> 1
A3: 500 | B3: 40 | C3: 0.837 | D3: 0.0021 | E3: 398.6 | F3: 0.1633 | K3: =A3*$H$2 -> 3447380 | L3: =(B3-32)*5/9+273.15 -> 277.59444 | M3: =C3 -> 0.837 | N3: =D3 -> 0.0021 | O3: =E3 -> 398.6 | P3: =F3 -> 0.1633
A4: 1000 | B4: 40 | C4: 0.9144 | D4: 0.004 | E4: 228.6 | F4: 0.0859 | K4: =A4*$H$2 -> 6894760 | L4: =(B4-32)*5/9+273.15 -> 277.59444 | M4: =C4 -> 0.9144 | N4: =D4 -> 0.004 | O4: =E4 -> 228.6 | P4: =F4 -> 0.0859
A5: 1500 | B5: 40 | C5: 0.9401 | D5: 0.0055 | E5: 170.9 | F5: 0.0602 | K5: =A5*$H$2 -> 10342140 | L5: =(B5-32)*5/9+273.15 -> 277.59444 | M5: =C5 -> 0.9401 | N5: =D5 -> 0.0055 | O5: =E5 -> 170.9 | P5: =F5 -> 0.0602
A6: 2000 | B6: 40 | C6: 0.9524 | D6: 0.007 | E6: 136 | F6: 0.0479 | K6: =A6*$H$2 -> 13789520 | L6: =(B6-32)*5/9+273.15 -> 277.59444 | M6: =C6 -> 0.9524 | N6: =D6 -> 0.007 | O6: =E6 -> 136 | P6: =F6 -> 0.0479
A7: 2500 | B7: 40 | C7: 0.9595 | D7: 0.0085 | E7: 112.9 | F7: 0.0408 | K7: =A7*$H$2 -> 17236900 | L7: =(B7-32)*5/9+273.15 -> 277.59444 | M7: =C7 -> 0.9595 | N7: =D7 -> 0.0085 | O7: =E7 -> 112.9 | P7: =F7 -> 0.0408
A8: 3000 | B8: 40 | C8: 0.964 | D8: 0.0102 | E8: 94.51 | F8: 0.0364 | K8: =A8*$H$2 -> 20684280 | L8: =(B8-32)*5/9+273.15 -> 277.59444 | M8: =C8 -> 0.964 | N8: =D8 -> 0.0102 | O8: =E8 -> 94.51 | P8: =F8 -> 0.0364
A9: 3500 | B9: 40 | C9: 0.9664 | D9: 0.012 | E9: 80.53 | F9: 0.034 | K9: =A9*$H$2 -> 24131660 | L9: =(B9-32)*5/9+273.15 -> 277.59444 | M9: =C9 -> 0.9664 | N9: =D9 -> 0.012 | O9: =E9 -> 80.53 | P9: =F9 -> 0.034
A10: 4000 | B10: 40 | C10: 0.969 | D10: 0.014 | E10: 69.21 | F10: 0.0314 | K10: =A10*$H$2 -> 27579040 | L10: =(B10-32)*5/9+273.15 -> 277.59444 | M10: =C10 -> 0.969 | N10: =D10 -> 0.014 | O10: =E10 -> 69.21 | P10: =F10 -> 0.0314
A11: 4500 | B11: 40 | C11: 0.9705 | D11: 0.016 | E11: 60.66 | F11: 0.03 | K11: =A11*$H$2 -> 31026420 | L11: =(B11-32)*5/9+273.15 -> 277.59444 | M11: =C11 -> 0.9705 | N11: =D11 -> 0.016 | O11: =E11 -> 60.66 | P11: =F11 -> 0.03
A12: 5000 | B12: 40 | C12: 0.9715 | D12: 0.0181 | E12: 53.67 | F12: 0.029 | K12: =A12*$H$2 -> 34473800 | L12: =(B12-32)*5/9+273.15 -> 277.59444 | M12: =C12 -> 0.9715 | N12: =D12 -> 0.0181 | O12: =E12 -> 53.67 | P12: =F12 -> 0.029
A13: 5500 | B13: 40 | C13: 0.9718 | D13: 0.0203 | E13: 47.87 | F13: 0.0288 | K13: =A13*$H$2 -> 37921180 | L13: =(B13-32)*5/9+273.15 -> 277.59444 | M13: =C13 -> 0.9718 | N13: =D13 -> 0.0203 | O13: =E13 -> 47.87 | P13: =F13 -> 0.0288
A14: 6000 | B14: 40 | C14: 0.972 | D14: 0.0225 | E14: 43.2 | F14: 0.0286 | K14: =A14*$H$2 -> 41368560 | L14: =(B14-32)*5/9+273.15 -> 277.59444 | M14: =C14 -> 0.972 | N14: =D14 -> 0.0225 | O14: =E14 -> 43.2 | P14: =F14 -> 0.0286
A15: 211.9 | B15: 100 | C15: 0 | D15: 0 | F15: 1 | K15: =A15*$H$2 -> 1460999.6 | L15: =(B15-32)*5/9+273.15 -> 310.92778 | M15: =C15 -> 0 | N15: =D15 -> 0 | P15: =F15 -> 1
A16: 500 | B16: 100 | C16: 0.535 | D16: 0.0025 | E16: 214 | F16: 0.4662 | K16: =A16*$H$2 -> 3447380 | L16: =(B16-32)*5/9+273.15 -> 310.92778 | M16: =C16 -> 0.535 | N16: =D16 -> 0.0025 | O16: =E16 -> 214 | P16: =F16 -> 0.4662
A17: 1000 | B17: 100 | C17: 0.749 | D17: 0.0056 | E17: 133.8 | F17: 0.2524 | K17: =A17*$H$2 -> 6894760 | L17: =(B17-32)*5/9+273.15 -> 310.92778 | M17: =C17 -> 0.749 | N17: =D17 -> 0.0056 | O17: =E17 -> 133.8 | P17: =F17 -> 0.2524
A18: 1500 | B18: 100 | C18: 0.8183 | D18: 0.0085 | E18: 96.27 | F18: 0.1793 | K18: =A18*$H$2 -> 10342140 | L18: =(B18-32)*5/9+273.15 -> 310.92778 | M18: =C18 -> 0.8183 | N18: =D18 -> 0.0085 | O18: =E18 -> 96.27 | P18: =F18 -> 0.1793
A19: 2000 | B19: 100 | C19: 0.8562 | D19: 0.0115 | E19: 74.45 | F19: 0.1457 | K19: =A19*$H$2 -> 13789520 | L19: =(B19-32)*5/9+273.15 -> 310.92778 | M19: =C19 -> 0.8562 | N19: =D19 -> 0.0115 | O19: =E19 -> 74.45 | P19: =F19 -> 0.1457
A20: 2500 | B20: 100 | C20: 0.8779 | D20: 0.0147 | E20: 59.72 | F20: 0.1239 | K20: =A20*$H$2 -> 17236900 | L20: =(B20-32)*5/9+273.15 -> 310.92778 | M20: =C20 -> 0.8779 | N20: =D20 -> 0.0147 | O20: =E20 -> 59.72 | P20: =F20 -> 0.1239
A21: 3000 | B21: 100 | C21: 0.8923 | D21: 0.0181 | E21: 49.3 | F21: 0.109 | K21: =A21*$H$2 -> 20684280 | L21: =(B21-32)*5/9+273.15 -> 310.92778 | M21: =C21 -> 0.8923 | N21: =D21 -> 0.0181 | O21: =E21 -> 49.3 | P21: =F21 -> 0.109
A22: 3500 | B22: 100 | C22: 0.9033 | D22: 0.0217 | E22: 41.63 | F22: 0.0982 | K22: =A22*$H$2 -> 24131660 | L22: =(B22-32)*5/9+273.15 -> 310.92778 | M22: =C22 -> 0.9033 | N22: =D22 -> 0.0217 | O22: =E22 -> 41.63 | P22: =F22 -> 0.0982
A23: 4000 | B23: 100 | C23: 0.911 | D23: 0.0255 | E23: 35.68 | F23: 0.0914 | K23: =A23*$H$2 -> 27579040 | L23: =(B23-32)*5/9+273.15 -> 310.92778 | M23: =C23 -> 0.911 | N23: =D23 -> 0.0255 | O23: =E23 -> 35.68 | P23: =F23 -> 0.0914
A24: 4500 | B24: 100 | C24: 0.9165 | D24: 0.0295 | E24: 31.07 | F24: 0.086 | K24: =A24*$H$2 -> 31026420 | L24: =(B24-32)*5/9+273.15 -> 310.92778 | M24: =C24 -> 0.9165 | N24: =D24 -> 0.0295 | O24: =E24 -> 31.07 | P24: =F24 -> 0.086
A25: 5000 | B25: 100 | C25: 0.9215 | D25: 0.0335 | E25: 27.48 | F25: 0.0812 | K25: =A25*$H$2 -> 34473800 | L25: =(B25-32)*5/9+273.15 -> 310.92778 | M25: =C25 -> 0.9215 | N25: =D25 -> 0.0335 | O25: =E25 -> 27.48 | P25: =F25 -> 0.0812
A26: 5500 | B26: 100 | C26: 0.9246 | D26: 0.0375 | E26: 24.66 | F26: 0.0784 | K26: =A26*$H$2 -> 37921180 | L26: =(B26-32)*5/9+273.15 -> 310.92778 | M26: =C26 -> 0.9246 | N26: =D26 -> 0.0375 | O26: =E26 -> 24.66 | P26: =F26 -> 0.0784
A27: 6000 | B27: 100 | C27: 0.927 | D27: 0.0413 | E27: 22.45 | F27: 0.0761 | K27: =A27*$H$2 -> 41368560 | L27: =(B27-32)*5/9+273.15 -> 310.92778 | M27: =C27 -> 0.927 | N27: =D27 -> 0.0413 | O27: =E27 -> 22.45 | P27: =F27 -> 0.0761
A28: 492.8 | B28: 160 | C28: 0 | D28: 0 | F28: 1 | K28: =A28*$H$2 -> 3397737.7 | L28: =(B28-32)*5/9+273.15 -> 344.26111 | M28: =C28 -> 0 | N28: =D28 -> 0 | P28: =F28 -> 1
A29: 500 | B29: 160 | C29: 0.0099 | D29: 0.0001 | E29: 99 | F29: 0.9902 | K29: =A29*$H$2 -> 3447380 | L29: =(B29-32)*5/9+273.15 -> 344.26111 | M29: =C29 -> 0.0099 | N29: =D29 -> 0.0001 | O29: =E29 -> 99 | P29: =F29 -> 0.9902
A30: 1000 | B30: 160 | C30: 0.422 | D30: 0.0065 | E30: 6.92 | F30: 0.5818 | K30: =A30*$H$2 -> 6894760 | L30: =(B30-32)*5/9+273.15 -> 344.26111 | M30: =C30 -> 0.422 | N30: =D30 -> 0.0065 | O30: =E30 -> 6.92 | P30: =F30 -> 0.5818
A31: 1500 | B31: 160 | C31: 0.5765 | D31: 0.0115 | E31: 50.13 | F31: 0.4284 | K31: =A31*$H$2 -> 10342140 | L31: =(B31-32)*5/9+273.15 -> 344.26111 | M31: =C31 -> 0.5765 | N31: =D31 -> 0.0115 | O31: =E31 -> 50.13 | P31: =F31 -> 0.4284
A32: 2000 | B32: 160 | C32: 0.6554 | D32: 0.017 | E32: 38.55 | F32: 0.351 | K32: =A32*$H$2 -> 13789520 | L32: =(B32-32)*5/9+273.15 -> 344.26111 | M32: =C32 -> 0.6554 | N32: =D32 -> 0.017 | O32: =E32 -> 38.55 | P32: =F32 -> 0.351
A33: 2500 | B33: 160 | C33: 0.7038 | D33: 0.023 | E33: 30.6 | F33: 0.3032 | K33: =A33*$H$2 -> 17236900 | L33: =(B33-32)*5/9+273.15 -> 344.26111 | M33: =C33 -> 0.7038 | N33: =D33 -> 0.023 | O33: =E33 -> 30.6 | P33: =F33 -> 0.3032
A34: 3000 | B34: 160 | C34: 0.7395 | D34: 0.029 | E34: 25.5 | F34: 0.2683 | K34: =A34*$H$2 -> 20684280 | L34: =(B34-32)*5/9+273.15 -> 344.26111 | M34: =C34 -> 0.7395 | N34: =D34 -> 0.029 | O34: =E34 -> 25.5 | P34: =F34 -> 0.2683
A35: 3500 | B35: 160 | C35: 0.764 | D35: 0.035 | E35: 21.83 | F35: 0.2446 | K35: =A35*$H$2 -> 24131660 | L35: =(B35-32)*5/9+273.15 -> 344.26111 | M35: =C35 -> 0.764 | N35: =D35 -> 0.035 | O35: =E35 -> 21.83 | P35: =F35 -> 0.2446
A36: 4000 | B36: 160 | C36: 0.7831 | D36: 0.041 | E36: 19.1 | F36: 0.2262 | K36: =A36*$H$2 -> 27579040 | L36: =(B36-32)*5/9+273.15 -> 344.26111 | M36: =C36 -> 0.7831 | N36: =D36 -> 0.041 | O36: =E36 -> 19.1 | P36: =F36 -> 0.2262
A37: 4500 | B37: 160 | C37: 0.798 | D37: 0.047 | E37: 16.98 | F37: 0.212 | K37: =A37*$H$2 -> 31026420 | L37: =(B37-32)*5/9+273.15 -> 344.26111 | M37: =C37 -> 0.798 | N37: =D37 -> 0.047 | O37: =E37 -> 16.98 | P37: =F37 -> 0.212
A38: 5000 | B38: 160 | C38: 0.8098 | D38: 0.053 | E38: 15.28 | F38: 0.2008 | K38: =A38*$H$2 -> 34473800 | L38: =(B38-32)*5/9+273.15 -> 344.26111 | M38: =C38 -> 0.8098 | N38: =D38 -> 0.053 | O38: =E38 -> 15.28 | P38: =F38 -> 0.2008
A39: 5500 | B39: 160 | C39: 0.8185 | D39: 0.059 | E39: 13.87 | F39: 0.1929 | K39: =A39*$H$2 -> 37921180 | L39: =(B39-32)*5/9+273.15 -> 344.26111 | M39: =C39 -> 0.8185 | N39: =D39 -> 0.059 | O39: =E39 -> 13.87 | P39: =F39 -> 0.1929
A40: 6000 | B40: 160 | C40: 0.8266 | D40: 0.065 | E40: 12.72 | F40: 0.1855 | K40: =A40*$H$2 -> 41368560 | L40: =(B40-32)*5/9+273.15 -> 344.26111 | M40: =C40 -> 0.8266 | N40: =D40 -> 0.065 | O40: =E40 -> 12.72 | P40: =F40 -> 0.1855
...

Sheet 0308-table5
A1: P(psig) | B1: T© | C1: x_H2*1e4 | E1: 1psig = pa | G1: P | H1: T | I1: x_H2
A2: 300 | B2: 25 | C2: 0.8755 | E2: 6894.7573 | G2: =$E$2*A2 -> 2068427.2 | H2: =B2+273.15 -> 298.15 | I2: =C2*0.0001 -> 8.755e-05
A3: 300 | B3: 0 | C3: 0.5565 | G3: =$E$2*A3 -> 2068427.2 | H3: =B3+273.15 -> 273.15 | I3: =C3*0.0001 -> 5.565e-05
A4: 300 | B4: -20 | C4: 0.3808 | G4: =$E$2*A4 -> 2068427.2 | H4: =B4+273.15 -> 253.15 | I4: =C4*0.0001 -> 3.808e-05
A5: 300 | B5: -41.6 | C5: 0.2447 | G5: =$E$2*A5 -> 2068427.2 | H5: =B5+273.15 -> 231.55 | I5: =C5*0.0001 -> 2.447e-05
A6: 300 | B6: -64 | C6: 0.1415 | G6: =$E$2*A6 -> 2068427.2 | H6: =B6+273.15 -> 209.15 | I6: =C6*0.0001 -> 1.415e-05

Sheet 0319-table1
A1: P(atm) | B1: T© | C1: cc of H2 at stp per g of ammonia | E1: rho_H2 at STP (kg/m3) | F1: M_H2 (kg/mol) | G1: M_NH3 (kg/mol) | I1: n_H2 | J1: n_NH3 | K1: x_H2 | M1: P | N1: T | P1: x_H2
A2: 100 | B2: 0 | C2: 6.7 | E2: 0.089932 | F2: =2.01588*0.001 -> 0.00201588 | G2: =17.0305*0.001 -> 0.0170305 | I2: =$E$2*C2*0.000001/$F$2 -> 0.00029889894 | J2: =1/($G$2*1000) -> 0.058718182 | K2: =I2/(I2+J2) -> 0.0050646175 | M2: =A2*101325 -> 10132500 | N2: =B2+273.15 -> 273.15 | P2: =K2 -> 0.0050646175
A3: 200 | B3: 0 | C3: 13.11 | I3: =$E$2*C3*0.000001/$F$2 -> 0.00058486047 | J3: =1/($G$2*1000) -> 0.058718182 | K3: =I3/(I3+J3) -> 0.0098622338 | M3: =A3*101325 -> 20265000 | N3: =B3+273.15 -> 273.15 | P3: =K3 -> 0.0098622338
A4: 400 | B4: 0 | C4: 24.33 | I4: =$E$2*C4*0.000001/$F$2 -> 0.0010854047 | J4: =1/($G$2*1000) -> 0.058718182 | K4: =I4/(I4+J4) -> 0.018149491 | M4: =A4*101325 -> 40530000 | N4: =B4+273.15 -> 273.15 | P4: =K4 -> 0.018149491
A5: 600 | B5: 0 | C5: 33.99 | I5: =$E$2*C5*0.000001/$F$2 -> 0.0015163545 | J5: =1/($G$2*1000) -> 0.058718182 | K5: =I5/(I5+J5) -> 0.02517417 | M5: =A5*101325 -> 60795000 | N5: =B5+273.15 -> 273.15 | P5: =K5 -> 0.02517417
A6: 800 | B6: 0 | C6: 42.33 | I6: =$E$2*C6*0.000001/$F$2 -> 0.0018884168 | J6: =1/($G$2*1000) -> 0.058718182 | K6: =I6/(I6+J6) -> 0.0311586 | M6: =A6*101325 -> 81060000 | N6: =B6+273.15 -> 273.15 | P6: =K6 -> 0.0311586
A7: 1000 | B7: 0 | C7: 49.77 | I7: =$E$2*C7*0.000001/$F$2 -> 0.0022203284 | J7: =1/($G$2*1000) -> 0.058718182 | K7: =I7/(I7+J7) -> 0.036435554 | M7: =A7*101325 -> 101325000 | N7: =B7+273.15 -> 273.15 | P7: =K7 -> 0.036435554

Sheet 0501-table2
A1: P(bar) | B1: T© | C1: L (cc of H2 in NTP per g of NH3) | D1: y_NH3 | F1: rho_H2 at NTP (kg/m3) | G1: M_H2 (kg/mol) | H1: M_NH3 (kg/mol) | J1: x_H2 | K1: x_NH3 | L1: y_H2 | N1: P | O1: T | P1: y_H2 | Q1: x_H2
A2: 202.15 | B2: 25 | C2: 20.78 | D2: 0.0696 | F2: 0.083795 | G2: =0.00201588 -> 0.00201588 | H2: =0.0170305 -> 0.0170305 | J2: =1/(1+1/(C2*0.000001/0.001*$H$2/$G$2*$F$2)) -> 0.014497203 | K2: =1-J2 -> 0.9855028 | L2: =1-D2 -> 0.9304 | N2: =A2*100000 -> 20215000 | O2: =B2+273.15 -> 298.15 | P2: =L2 -> 0.9304 | Q2: =J2 -> 0.014497203
A3: 100.7 | B3: 25 | C3: 10.19 | J3: =1/(1+1/(C3*0.000001/0.001*$H$2/$G$2*$F$2)) -> 0.007161985 | K3: =1-J3 -> 0.99283801 | N3: =A3*100000 -> 10070000 | O3: =B3+273.15 -> 298.15 | Q3: =J3 -> 0.007161985
A4: 100.2 | B4: 25 | D4: 0.1249 | L4: =1-D4 -> 0.8751 | N4: =A4*100000 -> 10020000 | O4: =B4+273.15 -> 298.15 | P4: =L4 -> 0.8751
A5: 53.45 | B5: 25 | C5: 4.89 | J5: =1/(1+1/(C5*0.000001/0.001*$H$2/$G$2*$F$2)) -> 0.00344976 | K5: =1-J5 -> 0.99655024 | N5: =A5*100000 -> 5345000 | O5: =B5+273.15 -> 298.15 | Q5: =J5 -> 0.00344976
A6: 28.9 | B6: 25 | C6: 2.2 | D6: 0.3855 | J6: =1/(1+1/(C6*0.000001/0.001*$H$2/$G$2*$F$2)) -> 0.0015549902 | K6: =1-J6 -> 0.99844501 | L6: =1-D6 -> 0.6145 | N6: =A6*100000 -> 2890000 | O6: =B6+273.15 -> 298.15 | P6: =L6 -> 0.6145 | Q6: =J6 -> 0.0015549902

Sheet 0501-table3
A1: P (Pa) | B1: T© | C1: y_NH3 | E1: P | F1: T | G1: y_H2
A2: =2*10.03*100000 -> 2006000 | B2: 25 | C2: 0.5165 | E2: =A2 -> 2006000 | F2: =B2+273.15 -> 298.15 | G2: =1-C2 -> 0.4835

Sheet 0502-table1
A1: pressure (atm) | B1: temperature © | C1: solubility (cc of H2 at STP per g of ammonia) | E1: rho_H2_STP (kg/m3) | F1: M_H2 (kg/mol) | G1: M_NH3 (kg/mol) | I1: n''_H2/n''_NH3 | K1: P | L1: T | M1: x_H2 | N1: x_NH3 | P1: y_H2 | Q1: x_H2 | R1: K_H2 | S1: K_NH3
A2: 50 | B2: 25 | C2: 4.471 | E2: 0.08988 | F2: =0.00201588 -> 0.00201588 | G2: =0.0170305 -> 0.0170305 | I2: =C2*0.000001/0.001*$G$2/$F$2*$E$2 -> 0.0033949271 | K2: =A2*101325 -> 5066250 | L2: =B2+273.15 -> 298.15 | M2: =1/(1+1/I2) -> 0.0033834406 | N2: =1-M2 -> 0.99661656 | Q2: =M2 -> 0.0033834406
A3: 100 | B3: 25 | C3: 9.875 | I3: =C3*0.000001/0.001*$G$2/$F$2*$E$2 -> 0.0074983014 | K3: =A3*101325 -> 10132500 | L3: =B3+273.15 -> 298.15 | M3: =1/(1+1/I3) -> 0.0074424953 | N3: =1-M3 -> 0.9925575 | Q3: =M3 -> 0.0074424953
A4: 200 | B4: 25 | C4: 20.077 | I4: =C4*0.000001/0.001*$G$2/$F$2*$E$2 -> 0.015244901 | K4: =A4*101325 -> 20265000 | L4: =B4+273.15 -> 298.15 | M4: =1/(1+1/I4) -> 0.015015984 | N4: =1-M4 -> 0.98498402 | Q4: =M4 -> 0.015015984
A5: 400 | B5: 25 | C5: 38.134 | I5: =C5*0.000001/0.001*$G$2/$F$2*$E$2 -> 0.028955972 | K5: =A5*101325 -> 40530000 | L5: =B5+273.15 -> 298.15 | M5: =1/(1+1/I5) -> 0.028141119 | N5: =1-M5 -> 0.97185888 | Q5: =M5 -> 0.028141119
A6: 600 | B6: 25 | C6: 53.711 | I6: =C6*0.000001/0.001*$G$2/$F$2*$E$2 -> 0.040783925 | K6: =A6*101325 -> 60795000 | L6: =B6+273.15 -> 298.15 | M6: =1/(1+1/I6) -> 0.039185776 | N6: =1-M6 -> 0.96081422 | Q6: =M6 -> 0.039185776
A7: 800 | B7: 25 | C7: 67.63 | I7: =C7*0.000001/0.001*$G$2/$F$2*$E$2 -> 0.051352924 | K7: =A7*101325 -> 81060000 | L7: =B7+273.15 -> 298.15 | M7: =1/(1+1/I7) -> 0.04884461 | N7: =1-M7 -> 0.95115539 | Q7: =M7 -> 0.04884461
A8: 1000 | B8: 25 | C8: 79.25 | I8: =C8*0.000001/0.001*$G$2/$F$2*$E$2 -> 0.060176241 | K8: =A8*101325 -> 101325000 | L8: =B8+273.15 -> 298.15 | M8: =1/(1+1/I8) -> 0.056760602 | N8: =1-M8 -> 0.9432394 | Q8: =M8 -> 0.056760602
A9: 50 | B9: 50 | C9: 5.1 | I9: =C9*0.000001/0.001*$G$2/$F$2*$E$2 -> 0.0038725404 | K9: =A9*101325 -> 5066250 | L9: =B9+273.15 -> 323.15 | M9: =1/(1+1/I9) -> 0.0038576017 | N9: =1-M9 -> 0.9961424 | Q9: =M9 -> 0.0038576017
A10: 100 | B10: 50 | C10: 13.486 | I10: =C10*0.000001/0.001*$G$2/$F$2*$E$2 -> 0.010240212 | K10: =A10*101325 -> 10132500 | L10: =B10+273.15 -> 323.15 | M10: =1/(1+1/I10) -> 0.010136413 | N10: =1-M10 -> 0.98986359 | Q10: =M10 -> 0.010136413
A11: 180 | B11: 50 | C11: 26.35 | I11: =C11*0.000001/0.001*$G$2/$F$2*$E$2 -> 0.020008126 | K11: =A11*101325 -> 18238500 | L11: =B11+273.15 -> 323.15 | M11: =1/(1+1/I11) -> 0.019615653 | N11: =1-M11 -> 0.98038435 | Q11: =M11 -> 0.019615653
A12: 200 | B12: 50 | C12: 29.39 | I12: =C12*0.000001/0.001*$G$2/$F$2*$E$2 -> 0.022316463 | K12: =A12*101325 -> 20265000 | L12: =B12+273.15 -> 323.15 | M12: =1/(1+1/I12) -> 0.02182931 | N12: =1-M12 -> 0.97817069 | Q12: =M12 -> 0.02182931
A13: 400 | B13: 50 | C13: 58.33 | I13: =C13*0.000001/0.001*$G$2/$F$2*$E$2 -> 0.044291232 | K13: =A13*101325 -> 40530000 | L13: =B13+273.15 -> 323.15 | M13: =1/(1+1/I13) -> 0.042412721 | N13: =1-M13 -> 0.95758728 | Q13: =M13 -> 0.042412721
A14: 600 | B14: 50 | C14: 83.48 | I14: =C14*0.000001/0.001*$G$2/$F$2*$E$2 -> 0.063388172 | K14: =A14*101325 -> 60795000 | L14: =B14+273.15 -> 323.15 | M14: =1/(1+1/I14) -> 0.059609627 | N14: =1-M14 -> 0.94039037 | Q14: =M14 -> 0.059609627
... A28: 1000 | B28: 100 | C28: 388.2 | I28: =C28*0.000001/0.001*$G$2/$F$2*$E$2 -> 0.29476867 | K28: =A28*101325 -> 101325000 | L28: =B28+273.15 -> 373.15 | M28: =1/(1+1/I28) -> 0.22766126 | N28: =1-M28 -> 0.77233874 | Q28: =M28 -> 0.22766126

Sheet 0504-figure1
A1: w_i (ppm) | B1: P_i (bar) | C1: T(K) | E1: w_H2 | G1: M_H2 (kg/mol) | H1: M_NH3 (kg/mol) | J1: P | K1: T | M1: x_H2
A2: 64.125759 | B2: 0.60549313 | C2: 293 | E2: =A2/10000 -> 0.0064125759 | G2: =0.00201588 -> 0.00201588 | H2: =0.0170305 -> 0.0170305 | J2: =B2*100000/M2 -> 1171053.2 | K2: =C2 -> 293 | M2: =E2/($G$2/$H$2*(1-E2)+E2) -> 0.051705008
A3: 81.330858 | B3: 0.79775281 | C3: 293 | E3: =A3/10000 -> 0.0081330858 | J3: =B3*100000/M3 -> 1231380.6 | K3: =C3 -> 293 | M3: =E3/($G$2/$H$2*(1-E3)+E3) -> 0.064785233
A4: 97.293889 | B4: 0.99750312 | C4: 293 | E4: =A4/10000 -> 0.0097293889 | J4: =B4*100000/M4 -> 1301516.2 | K4: =C4 -> 293 | M4: =E4/($G$2/$H$2*(1-E4)+E4) -> 0.076641622

Sheet 0505-table1
A1: P(atm) | B1: Volume of H₂ dissolved (cm³ per 100 cm³ NH₃) | C1: T© | E1: rho_NH3 (kg/m3) | F1: rho_H2 at NTP (kg/m3) | G1: M_H2 (kg/mol) | H1: M_NH3 (kg/mol) | J1: n_H2 | K1: n_NH3 | M1: x_H2 | O1: P | P1: T | Q1: y_H2 | R1: x_H2
A2: 15 | B2: 97.3 | C2: 25 | E2: 603.68 | F2: 0.083795 | G2: =0.00201588 -> 0.00201588 | H2: =0.0170305 -> 0.0170305 | J2: =$F$2*B2*0.000001/$G$2 -> 0.0040445133 | K2: =E2*100*0.000001/$H$2 -> 3.5446992 | M2: =J2/(J2+K2) -> 0.0011397028 | O2: =A2*101325 -> 1519875 | P2: =C2+273.15 -> 298.15 | R2: =M2 -> 0.0011397028
A3: 25 | B3: 161.1 | C3: 25 | E3: 604.64 | J3: =$F$2*B3*0.000001/$G$2 -> 0.0066965169 | K3: =E3*100*0.000001/$H$2 -> 3.5503362 | M3: =J3/(J3+K3) -> 0.0018826133 | O3: =A3*101325 -> 2533125 | P3: =C3+273.15 -> 298.15 | R3: =M3 -> 0.0018826133
A4: 50 | B4: 303 | C4: 25 | E4: 606.99 | J4: =$F$2*B4*0.000001/$G$2 -> 0.012594939 | K4: =E4*100*0.000001/$H$2 -> 3.5641349 | M4: =J4/(J4+K4) -> 0.0035213559 | O4: =A4*101325 -> 5066250 | P4: =C4+273.15 -> 298.15 | R4: =M4 -> 0.0035213559
A5: 70 | B5: 434 | C5: 25 | E5: 608.8 | J5: =$F$2*B5*0.000001/$G$2 -> 0.018040275 | K5: =E5*100*0.000001/$H$2 -> 3.5747629 | M5: =J5/(J5+K5) -> 0.0050212255 | O5: =A5*101325 -> 7092750 | P5: =C5+273.15 -> 298.15 | R5: =M5 -> 0.0050212255
A6: 100 | B6: 610.6 | C6: 25 | E6: 611.45 | J6: =$F$2*B6*0.000001/$G$2 -> 0.025381088 | K6: =E6*100*0.000001/$H$2 -> 3.5903232 | M6: =J6/(J6+K6) -> 0.0070196801 | O6: =A6*101325 -> 10132500 | P6: =C6+273.15 -> 298.15 | R6: =M6 -> 0.0070196801
A7: 150 | B7: 921.8 | C7: 25 | E7: 615.66 | J7: =$F$2*B7*0.000001/$G$2 -> 0.038316879 | K7: =E7*100*0.000001/$H$2 -> 3.6150436 | M7: =J7/(J7+K7) -> 0.010488119 | O7: =A7*101325 -> 15198750 | P7: =C7+273.15 -> 298.15 | R7: =M7 -> 0.010488119
A8: 200 | B8: 1218.5 | C8: 25 | E8: 619.65 | J8: =$F$2*B8*0.000001/$G$2 -> 0.050649943 | K8: =E8*100*0.000001/$H$2 -> 3.6384722 | M8: =J8/(J8+K8) -> 0.013729538 | O8: =A8*101325 -> 20265000 | P8: =C8+273.15 -> 298.15 | R8: =M8 -> 0.013729538
A9: 250 | B9: 1575 | C9: 25 | E9: 623.44 | J9: =$F$2*B9*0.000001/$G$2 -> 0.065468741 | K9: =E9*100*0.000001/$H$2 -> 3.6607263 | M9: =J9/(J9+K9) -> 0.017569864 | O9: =A9*101325 -> 25331250 | P9: =C9+273.15 -> 298.15 | R9: =M9 -> 0.017569864
E10: (these values are from NIST)

Sheet 0506-table1
A1: P(atm) | B1: T© | C1: y_NH3 | E1: P | F1: T | G1: y_H2
A2: 100 | B2: 0 | C2: 0.056 | E2: =A2*101325 -> 10132500 | F2: =B2+273.15 -> 273.15 | G2: =1-C2 -> 0.944
A3: 150 | B3: 0 | C3: 0.04 | E3: =A3*101325 -> 15198750 | F3: =B3+273.15 -> 273.15 | G3: =1-C3 -> 0.96
A4: 200 | B4: 0 | C4: 0.03 | E4: =A4*101325 -> 20265000 | F4: =B4+273.15 -> 273.15 | G4: =1-C4 -> 0.97
A5: 250 | B5: 0 | C5: 0.024 | E5: =A5*101325 -> 25331250 | F5: =B5+273.15 -> 273.15 | G5: =1-C5 -> 0.976
A6: 300 | B6: 0 | C6: 0.022 | E6: =A6*101325 -> 30397500 | F6: =B6+273.15 -> 273.15 | G6: =1-C6 -> 0.978
A7: 100 | B7: 25 | C7: 0.104 | E7: =A7*101325 -> 10132500 | F7: =B7+273.15 -> 298.15 | G7: =1-C7 -> 0.896
A8: 150 | B8: 25 | C8: 0.082 | E8: =A8*101325 -> 15198750 | F8: =B8+273.15 -> 298.15 | G8: =1-C8 -> 0.918
A9: 200 | B9: 25 | C9: 0.063 | E9: =A9*101325 -> 20265000 | F9: =B9+273.15 -> 298.15 | G9: =1-C9 -> 0.937
A10: 250 | B10: 25 | C10: 0.055 | E10: =A10*101325 -> 25331250 | F10: =B10+273.15 -> 298.15 | G10: =1-C10 -> 0.945
A11: 300 | B11: 25 | C11: 0.045 | E11: =A11*101325 -> 30397500 | F11: =B11+273.15 -> 298.15 | G11: =1-C11 -> 0.955
A12: 100 | B12: 50 | C12: 0.188 | E12: =A12*101325 -> 10132500 | F12: =B12+273.15 -> 323.15 | G12: =1-C12 -> 0.812
A13: 150 | B13: 50 | C13: 0.148 | E13: =A13*101325 -> 15198750 | F13: =B13+273.15 -> 323.15 | G13: =1-C13 -> 0.852
... A21: 300 | B21: 75 | C21: 0.122 | E21: =A21*101325 -> 30397500 | F21: =B21+273.15 -> 348.15 | G21: =1-C21 -> 0.878
A23: both Copilot and google translate were used to obtain the data from table 1
A24: the other tables do not contain any information on ammonia-hydrogen system
